Workbook

Sheet Медиаплан
A1: МЕДИАПЛАН — ВБ РЕКЛАМА
A2: Синее — от руководителя. Жёлтое — твои цифры. Серое — считается само.
A4: ▼ ИЮЛЬ 2026
A5: Бюджет на месяц, ₽ | B5: 30000 | C5: Целевой DRR | D5: 0.1 | F5: Средний чек, ₽ | G5: 856 | I5: % выкупа | J5: 0.95
A6: Рекламная кампания | B6: Бюджет, ₽ | C6: Прогноз охвата | D6: CTR % | E6: Клики | F6: CR в заказ % | G6: Заказы | H6: CPO, ₽ | I6: Выкупы | J6: Стоимость выкупа, ₽ | K6: Выручка, ₽ | L6: DRR
A7: тестовые | B7: 15000 | C7: 10000 | D7: 0.05 | E7: =IF(OR(C7="",D7=""),"",ROUND(C7*D7,0)) -> 500 | F7: 0.5 | G7: =IF(OR(E7="",F7=""),"",ROUND(E7*F7,0)) -> 250 | H7: =IF(N(G7)=0,"",B7/G7) -> 60 | I7: =IF(OR(N(G7)=0,$J$5=""),"",ROUND(G7*$J$5,0)) -> 238 | J7: =IF(N(I7)=0,"",B7/I7) -> 63.02521 | K7: =IF(N(I7)=0,"",I7*$G$5) -> 203728 | L7: =IF(N(K7)=0,"",B7/K7) -> 0.073627582
E8: =IF(OR(C8="",D8=""),"",ROUND(C8*D8,0)) | G8: =IF(OR(E8="",F8=""),"",ROUND(E8*F8,0)) | H8: =IF(N(G8)=0,"",B8/G8) | I8: =IF(OR(N(G8)=0,$J$5=""),"",ROUND(G8*$J$5,0)) | J8: =IF(N(I8)=0,"",B8/I8) | K8: =IF(N(I8)=0,"",I8*$G$5) | L8: =IF(N(K8)=0,"",B8/K8)
E9: =IF(OR(C9="",D9=""),"",ROUND(C9*D9,0)) | G9: =IF(OR(E9="",F9=""),"",ROUND(E9*F9,0)) | H9: =IF(N(G9)=0,"",B9/G9) | I9: =IF(OR(N(G9)=0,$J$5=""),"",ROUND(G9*$J$5,0)) | J9: =IF(N(I9)=0,"",B9/I9) | K9: =IF(N(I9)=0,"",I9*$G$5) | L9: =IF(N(K9)=0,"",B9/K9)
E10: =IF(OR(C10="",D10=""),"",ROUND(C10*D10,0)) | G10: =IF(OR(E10="",F10=""),"",ROUND(E10*F10,0)) | H10: =IF(N(G10)=0,"",B10/G10) | I10: =IF(OR(N(G10)=0,$J$5=""),"",ROUND(G10*$J$5,0)) | J10: =IF(N(I10)=0,"",B10/I10) | K10: =IF(N(I10)=0,"",I10*$G$5) | L10: =IF(N(K10)=0,"",B10/K10)
E11: =IF(OR(C11="",D11=""),"",ROUND(C11*D11,0)) | G11: =IF(OR(E11="",F11=""),"",ROUND(E11*F11,0)) | H11: =IF(N(G11)=0,"",B11/G11) | I11: =IF(OR(N(G11)=0,$J$5=""),"",ROUND(G11*$J$5,0)) | J11: =IF(N(I11)=0,"",B11/I11) | K11: =IF(N(I11)=0,"",I11*$G$5) | L11: =IF(N(K11)=0,"",B11/K11)
E12: =IF(OR(C12="",D12=""),"",ROUND(C12*D12,0)) | G12: =IF(OR(E12="",F12=""),"",ROUND(E12*F12,0)) | H12: =IF(N(G12)=0,"",B12/G12) | I12: =IF(OR(N(G12)=0,$J$5=""),"",ROUND(G12*$J$5,0)) | J12: =IF(N(I12)=0,"",B12/I12) | K12: =IF(N(I12)=0,"",I12*$G$5) | L12: =IF(N(K12)=0,"",B12/K12)
E13: =IF(OR(C13="",D13=""),"",ROUND(C13*D13,0)) | G13: =IF(OR(E13="",F13=""),"",ROUND(E13*F13,0)) | H13: =IF(N(G13)=0,"",B13/G13) | I13: =IF(OR(N(G13)=0,$J$5=""),"",ROUND(G13*$J$5,0)) | J13: =IF(N(I13)=0,"",B13/I13) | K13: =IF(N(I13)=0,"",I13*$G$5) | L13: =IF(N(K13)=0,"",B13/K13)
A14: ИТОГО | B14: =SUM(B7:B13) -> 15000 | C14: =SUM(C7:C13) -> 10000 | E14: =SUM(E7:E13) -> 500 | G14: =SUM(G7:G13) -> 250 | H14: =IF(N(G14)=0,"",B14/G14) -> 60 | I14: =SUM(I7:I13) -> 238 | J14: =IF(N(I14)=0,"",B14/I14) -> 63.02521 | K14: =SUM(K7:K13) -> 203728 | L14: =IF(N(K14)=0,"",B14/K14) -> 0.073627582
A15: Вердикт | B15: =IF(OR(N(K14)=0,N($D$5)=0),"— заполни цели",IF(AND(B14<=$B$5,B14/K14<=$D$5),"OK: в лимите и по DRR",IF(B14>$B$5,"БЮДЖЕТ ПРЕВЫШЕН","DRR ВЫШЕ ЦЕЛЕВОГО"))) -> OK: в лимите и по DRR
A17: ▼ АВГУСТ 2026
A18: Бюджет на месяц, ₽ | B18: 70500 | C18: Целевой DRR | D18: 0.1 | F18: Средний чек, ₽ | G18: 856 | I18: % выкупа | J18: 0.95
A19: Рекламная кампания | B19: Бюджет, ₽ | C19: Прогноз охвата | D19: CTR % | E19: Клики | F19: CR в заказ % | G19: Заказы | H19: CPO, ₽ | I19: Выкупы | J19: Стоимость выкупа, ₽ | K19: Выручка, ₽ | L19: DRR
A20: ВБ Продвижение СPM (просмотры) | B20: 35000 | C20: 190000 | D20: 0.064 | E20: =IF(OR(C20="",D20=""),"",ROUND(C20*D20,0)) -> 12160 | F20: 0.051 | G20: =IF(OR(E20="",F20=""),"",ROUND(E20*F20,0)) -> 620 | H20: =IF(N(G20)=0,"",B20/G20) -> 56.451613 | I20: =IF(OR(N(G20)=0,$J$18=""),"",ROUND(G20*$J$18,0)) -> 589 | J20: =IF(N(I20)=0,"",B20/I20) -> 59.42275 | K20: =IF(N(I20)=0,"",I20*$G$18) -> 504184 | L20: =IF(N(K20)=0,"",B20/K20) -> 0.069419101
A21: ВБ Продвижение СPC (Клик) | B21: 35000 | C21: 70000 | D21: 0.034 | E21: =IF(OR(C21="",D21=""),"",ROUND(C21*D21,0)) -> 2380 | F21: 0.13 | G21: =IF(OR(E21="",F21=""),"",ROUND(E21*F21,0)) -> 309 | H21: =IF(N(G21)=0,"",B21/G21) -> 113.26861 | I21: =IF(OR(N(G21)=0,$J$18=""),"",ROUND(G21*$J$18,0)) -> 294 | J21: =IF(N(I21)=0,"",B21/I21) -> 119.04762 | K21: =IF(N(I21)=0,"",I21*$G$18) -> 251664 | L21: =IF(N(K21)=0,"",B21/K21) -> 0.13907432
E22: =IF(OR(C22="",D22=""),"",ROUND(C22*D22,0)) | G22: =IF(OR(E22="",F22=""),"",ROUND(E22*F22,0)) | H22: =IF(N(G22)=0,"",B22/G22) | I22: =IF(OR(N(G22)=0,$J$18=""),"",ROUND(G22*$J$18,0)) | J22: =IF(N(I22)=0,"",B22/I22) | K22: =IF(N(I22)=0,"",I22*$G$18) | L22: =IF(N(K22)=0,"",B22/K22)
E23: =IF(OR(C23="",D23=""),"",ROUND(C23*D23,0)) | G23: =IF(OR(E23="",F23=""),"",ROUND(E23*F23,0)) | H23: =IF(N(G23)=0,"",B23/G23) | I23: =IF(OR(N(G23)=0,$J$18=""),"",ROUND(G23*$J$18,0)) | J23: =IF(N(I23)=0,"",B23/I23) | K23: =IF(N(I23)=0,"",I23*$G$18) | L23: =IF(N(K23)=0,"",B23/K23)
E24: =IF(OR(C24="",D24=""),"",ROUND(C24*D24,0)) | G24: =IF(OR(E24="",F24=""),"",ROUND(E24*F24,0)) | H24: =IF(N(G24)=0,"",B24/G24) | I24: =IF(OR(N(G24)=0,$J$18=""),"",ROUND(G24*$J$18,0)) | J24: =IF(N(I24)=0,"",B24/I24) | K24: =IF(N(I24)=0,"",I24*$G$18) | L24: =IF(N(K24)=0,"",B24/K24)
E25: =IF(OR(C25="",D25=""),"",ROUND(C25*D25,0)) | G25: =IF(OR(E25="",F25=""),"",ROUND(E25*F25,0)) | H25: =IF(N(G25)=0,"",B25/G25) | I25: =IF(OR(N(G25)=0,$J$18=""),"",ROUND(G25*$J$18,0)) | J25: =IF(N(I25)=0,"",B25/I25) | K25: =IF(N(I25)=0,"",I25*$G$18) | L25: =IF(N(K25)=0,"",B25/K25)
E26: =IF(OR(C26="",D26=""),"",ROUND(C26*D26,0)) | G26: =IF(OR(E26="",F26=""),"",ROUND(E26*F26,0)) | H26: =IF(N(G26)=0,"",B26/G26) | I26: =IF(OR(N(G26)=0,$J$18=""),"",ROUND(G26*$J$18,0)) | J26: =IF(N(I26)=0,"",B26/I26) | K26: =IF(N(I26)=0,"",I26*$G$18) | L26: =IF(N(K26)=0,"",B26/K26)
A27: ИТОГО | B27: =SUM(B20:B26) -> 70000 | C27: =SUM(C20:C26) -> 260000 | E27: =SUM(E20:E26) -> 14540 | G27: =SUM(G20:G26) -> 929 | H27: =IF(N(G27)=0,"",B27/G27) -> 75.349839 | I27: =SUM(I20:I26) -> 883 | J27: =IF(N(I27)=0,"",B27/I27) -> 79.275198 | K27: =SUM(K20:K26) -> 755848 | L27: =IF(N(K27)=0,"",B27/K27) -> 0.092611213
A28: Вердикт | B28: =IF(OR(N(K27)=0,N($D$18)=0),"— заполни цели",IF(AND(B27<=$B$18,B27/K27<=$D$18),"OK: в лимите и по DRR",IF(B27>$B$18,"БЮДЖЕТ ПРЕВЫШЕН","DRR ВЫШЕ ЦЕЛЕВОГО"))) -> OK: в лимите и по DRR
A30: ▼ СЕНТЯБРЬ 2026
A31: Бюджет на месяц, ₽ | B31: 140000 | C31: Целевой DRR | D31: 0.1 | F31: Средний чек, ₽ | G31: 900 | I31: % выкупа | J31: 0.95
A32: Рекламная кампания | B32: Бюджет, ₽ | C32: Прогноз охвата | D32: CTR % | E32: Клики | F32: CR в заказ % | G32: Заказы | H32: CPO, ₽ | I32: Выкупы | J32: Стоимость выкупа, ₽ | K32: Выручка, ₽ | L32: DRR
A33: ВБ Продвижение СPM (просмотры) | B33: 35000 | C33: 153900 | D33: 0.0284 | E33: =IF(OR(C33="",D33=""),"",ROUND(C33*D33,0)) -> 4371 | F33: 0.0364 | G33: =IF(OR(E33="",F33=""),"",ROUND(E33*F33,0)) -> 159 | H33: =IF(N(G33)=0,"",B33/G33) -> 220.12579 | I33: =IF(OR(N(G33)=0,$J$31=""),"",ROUND(G33*$J$31,0)) -> 151 | J33: =IF(N(I33)=0,"",B33/I33) -> 231.78808 | K33: =IF(N(I33)=0,"",I33*$G$31) -> 135900 | L33: =IF(N(K33)=0,"",B33/K33) -> 0.25754231
A34: ВБ Продвижение СPC (Клик) | B34: 35000 | C34: 59372 | D34: 0.0577 | E34: =IF(OR(C34="",D34=""),"",ROUND(C34*D34,0)) -> 3426 | F34: 0.0938 | G34: =IF(OR(E34="",F34=""),"",ROUND(E34*F34,0)) -> 321 | H34: =IF(N(G34)=0,"",B34/G34) -> 109.03427 | I34: =IF(OR(N(G34)=0,$J$31=""),"",ROUND(G34*$J$31,0)) -> 305 | J34: =IF(N(I34)=0,"",B34/I34) -> 114.7541 | K34: =IF(N(I34)=0,"",I34*$G$31) -> 274500 | L34: =IF(N(K34)=0,"",B34/K34) -> 0.12750455
A35: ОЗОН | B35: 70000 | C35: 13100 | D35: 0.068 | E35: =IF(OR(C35="",D35=""),"",ROUND(C35*D35,0)) -> 891 | F35: 0.46 | G35: =IF(OR(E35="",F35=""),"",ROUND(E35*F35,0)) -> 410 | H35: =IF(N(G35)=0,"",B35/G35) -> 170.73171 | I35: =IF(OR(N(G35)=0,$J$31=""),"",ROUND(G35*$J$31,0)) -> 390 | J35: =IF(N(I35)=0,"",B35/I35) -> 179.48718 | K35: =IF(N(I35)=0,"",I35*$G$31) -> 351000 | L35: =IF(N(K35)=0,"",B35/K35) -> 0.1994302
E36: =IF(OR(C36="",D36=""),"",ROUND(C36*D36,0)) | G36: =IF(OR(E36="",F36=""),"",ROUND(E36*F36,0)) | H36: =IF(N(G36)=0,"",B36/G36) | I36: =IF(OR(N(G36)=0,$J$31=""),"",ROUND(G36*$J$31,0)) | J36: =IF(N(I36)=0,"",B36/I36) | K36: =IF(N(I36)=0,"",I36*$G$31) | L36: =IF(N(K36)=0,"",B36/K36)
E37: =IF(OR(C37="",D37=""),"",ROUND(C37*D37,0)) | G37: =IF(OR(E37="",F37=""),"",ROUND(E37*F37,0)) | H37: =IF(N(G37)=0,"",B37/G37) | I37: =IF(OR(N(G37)=0,$J$31=""),"",ROUND(G37*$J$31,0)) | J37: =IF(N(I37)=0,"",B37/I37) | K37: =IF(N(I37)=0,"",I37*$G$31) | L37: =IF(N(K37)=0,"",B37/K37)
E38: =IF(OR(C38="",D38=""),"",ROUND(C38*D38,0)) | G38: =IF(OR(E38="",F38=""),"",ROUND(E38*F38,0)) | H38: =IF(N(G38)=0,"",B38/G38) | I38: =IF(OR(N(G38)=0,$J$31=""),"",ROUND(G38*$J$31,0)) | J38: =IF(N(I38)=0,"",B38/I38) | K38: =IF(N(I38)=0,"",I38*$G$31) | L38: =IF(N(K38)=0,"",B38/K38)
E39: =IF(OR(C39="",D39=""),"",ROUND(C39*D39,0)) | G39: =IF(OR(E39="",F39=""),"",ROUND(E39*F39,0)) | H39: =IF(N(G39)=0,"",B39/G39) | I39: =IF(OR(N(G39)=0,$J$31=""),"",ROUND(G39*$J$31,0)) | J39: =IF(N(I39)=0,"",B39/I39) | K39: =IF(N(I39)=0,"",I39*$G$31) | L39: =IF(N(K39)=0,"",B39/K39)
A40: ИТОГО | B40: =SUM(B33:B39) -> 140000 | C40: =SUM(C33:C39) -> 226372 | E40: =SUM(E33:E39) -> 8688 | G40: =SUM(G33:G39) -> 890 | H40: =IF(N(G40)=0,"",B40/G40) -> 157.30337 | I40: =SUM(I33:I39) -> 846 | J40: =IF(N(I40)=0,"",B40/I40) -> 165.48463 | K40: =SUM(K33:K39) -> 761400 | L40: =IF(N(K40)=0,"",B40/K40) -> 0.18387182
A41: Вердикт | B41: =IF(OR(N(K40)=0,N($D$31)=0),"— заполни цели",IF(AND(B40<=$B$31,B40/K40<=$D$31),"OK: в лимите и по DRR",IF(B40>$B$31,"БЮДЖЕТ ПРЕВЫШЕН","DRR ВЫШЕ ЦЕЛЕВОГО"))) -> DRR ВЫШЕ ЦЕЛЕВОГО
A43: ▼ ОКТЯБРЬ 2026
A44: Бюджет на месяц, ₽ | C44: Целевой DRR | F44: Средний чек, ₽ | I44: % выкупа
...

Sheet Отчёт по неделям
A1: ОТЧЁТ ПО НЕДЕЛЯМ — Триггер · факт vs план | Y1: =IF($B$15="Весь период","<>",$B$15) -> <>
A2: Синее — план (из «Медиаплан»). Жёлтое — вносишь вручную. Серое — считается само. Зелёное — итоги. Слева ▼ сворачивает недели и месяцы. | Y2: =IF($D$15="Все недели","<>",$D$15) -> <>
A4: СВОДКА · ВЫРУЧКА: ПЛАН vs ФАКТ ПО МЕСЯЦАМ
A5: Месяц | B5: Выручка план, ₽ | C5: Выручка факт, ₽ | D5: Выполнение % | F5: DRR факт | G5: Заказы | I5: Выкупы
A6: Июль | B6: =T25 -> 203728 | C6: =P25 -> 140469 | D6: =IF(N(B6)=0,"",C6/B6) -> 0.68949285 | F6: =S25 -> 0.19866305 | G6: =I25 -> 214 | I6: =L25 -> 208
A7: Август | B7: =T56 -> 755848 | C7: =P56 -> 299234 | D7: =IF(N(B7)=0,"",C7/B7) -> 0.39589177 | F7: =S56 -> 0.24629888 | G7: =I56 -> 498 | I7: =L56 -> 425
A8: Сентябрь | B8: =T87 -> 761400 | C8: =P87 -> 747664 | D8: =IF(N(B8)=0,"",C8/B8) -> 0.98195955 | F8: =S87 -> 0.24506329 | G8: =I87 -> 1150 | I8: =L87 -> 1072
A9: Октябрь | B9: =T129 -> 0 | C9: =P129 -> 0 | D9: =IF(N(B9)=0,"",C9/B9) | F9: =S129 | G9: =I129 -> 0 | I9: =L129 -> 0
A10: Ноябрь | B10: =T160 -> 0 | C10: =P160 -> 0 | D10: =IF(N(B10)=0,"",C10/B10) | F10: =S160 | G10: =I160 -> 0 | I10: =L160 -> 0
A11: Декабрь | B11: =T191 -> 0 | C11: =P191 -> 0 | D11: =IF(N(B11)=0,"",C11/B11) | F11: =S191 | G11: =I191 -> 0 | I11: =L191 -> 0
A12: ИТОГО | B12: =SUM(B6:B11) -> 1720976 | C12: =SUM(C6:C11) -> 1187367 | D12: =IF(N(B12)=0,"",C12/B12) -> 0.68993815 | F12: =IF(N(C12)=0,"",SUMIFS(C25:C221,V25:V221,"<>")/C12) -> 0.22729114 | G12: =SUM(G6:G11) -> 1862 | I12: =SUM(I6:I11) -> 1705
A14: СВОДКА · ФАКТ ПО ПРОДУКТАМ (срез по месяцу/неделе · новый продукт впиши в пустую строку «Продукт»)
A15: Месяц: | B15: Весь период | C15: Неделя: | D15: Все недели
A16: Продукт | B16: Бюджет, ₽ | C16: Заказы | D16: Выкупы | F16: Выручка факт, ₽ | G16: CPO, ₽ | I16: Ст.выкупа, ₽ | J16: DRR
A17: Триггер | B17: =IF($A$17="","",SUMIFS($C$25:$C$221,$V$25:$V$221,$Y$1,$W$25:$W$221,$Y$2,$B$25:$B$221,$A$17)) -> 258515 | C17: =IF($A$17="","",SUMIFS($I$25:$I$221,$V$25:$V$221,$Y$1,$W$25:$W$221,$Y$2,$B$25:$B$221,$A$17)) -> 1807 | D17: =IF($A$17="","",SUMIFS($L$25:$L$221,$V$25:$V$221,$Y$1,$W$25:$W$221,$Y$2,$B$25:$B$221,$A$17)) -> 1656 | F17: =IF($A$17="","",SUMIFS($P$25:$P$221,$V$25:$V$221,$Y$1,$W$25:$W$221,$Y$2,$B$25:$B$221,$A$17)) -> 1136556 | G17: =IF(N(C17)=0,"",B17/C17) -> 143.06309 | I17: =IF(N(D17)=0,"",B17/D17) -> 156.10809 | J17: =IF(N(F17)=0,"",B17/F17) -> 0.2274547
A18: Аппликатор | B18: =IF($A$18="","",SUMIFS($C$25:$C$221,$V$25:$V$221,$Y$1,$W$25:$W$221,$Y$2,$B$25:$B$221,$A$18)) -> 10411 | C18: =IF($A$18="","",SUMIFS($I$25:$I$221,$V$25:$V$221,$Y$1,$W$25:$W$221,$Y$2,$B$25:$B$221,$A$18)) -> 6 | D18: =IF($A$18="","",SUMIFS($L$25:$L$221,$V$25:$V$221,$Y$1,$W$25:$W$221,$Y$2,$B$25:$B$221,$A$18)) -> 6 | F18: =IF($A$18="","",SUMIFS($P$25:$P$221,$V$25:$V$221,$Y$1,$W$25:$W$221,$Y$2,$B$25:$B$221,$A$18)) -> 17385 | G18: =IF(N(C18)=0,"",B18/C18) -> 1735.1667 | I18: =IF(N(D18)=0,"",B18/D18) -> 1735.1667 | J18: =IF(N(F18)=0,"",B18/F18) -> 0.59884958
B19: =IF($A$19="","",SUMIFS($C$25:$C$221,$V$25:$V$221,$Y$1,$W$25:$W$221,$Y$2,$B$25:$B$221,$A$19)) | C19: =IF($A$19="","",SUMIFS($I$25:$I$221,$V$25:$V$221,$Y$1,$W$25:$W$221,$Y$2,$B$25:$B$221,$A$19)) | D19: =IF($A$19="","",SUMIFS($L$25:$L$221,$V$25:$V$221,$Y$1,$W$25:$W$221,$Y$2,$B$25:$B$221,$A$19)) | F19: =IF($A$19="","",SUMIFS($P$25:$P$221,$V$25:$V$221,$Y$1,$W$25:$W$221,$Y$2,$B$25:$B$221,$A$19)) | G19: =IF(N(C19)=0,"",B19/C19) | I19: =IF(N(D19)=0,"",B19/D19) | J19: =IF(N(F19)=0,"",B19/F19)
B20: =IF($A$20="","",SUMIFS($C$25:$C$221,$V$25:$V$221,$Y$1,$W$25:$W$221,$Y$2,$B$25:$B$221,$A$20)) | C20: =IF($A$20="","",SUMIFS($I$25:$I$221,$V$25:$V$221,$Y$1,$W$25:$W$221,$Y$2,$B$25:$B$221,$A$20)) | D20: =IF($A$20="","",SUMIFS($L$25:$L$221,$V$25:$V$221,$Y$1,$W$25:$W$221,$Y$2,$B$25:$B$221,$A$20)) | F20: =IF($A$20="","",SUMIFS($P$25:$P$221,$V$25:$V$221,$Y$1,$W$25:$W$221,$Y$2,$B$25:$B$221,$A$20)) | G20: =IF(N(C20)=0,"",B20/C20) | I20: =IF(N(D20)=0,"",B20/D20) | J20: =IF(N(F20)=0,"",B20/F20)
B21: =IF($A$21="","",SUMIFS($C$25:$C$221,$V$25:$V$221,$Y$1,$W$25:$W$221,$Y$2,$B$25:$B$221,$A$21)) | C21: =IF($A$21="","",SUMIFS($I$25:$I$221,$V$25:$V$221,$Y$1,$W$25:$W$221,$Y$2,$B$25:$B$221,$A$21)) | D21: =IF($A$21="","",SUMIFS($L$25:$L$221,$V$25:$V$221,$Y$1,$W$25:$W$221,$Y$2,$B$25:$B$221,$A$21)) | F21: =IF($A$21="","",SUMIFS($P$25:$P$221,$V$25:$V$221,$Y$1,$W$25:$W$221,$Y$2,$B$25:$B$221,$A$21)) | G21: =IF(N(C21)=0,"",B21/C21) | I21: =IF(N(D21)=0,"",B21/D21) | J21: =IF(N(F21)=0,"",B21/F21)
A22: ИТОГО | B22: =SUMIFS($C$25:$C$221,$V$25:$V$221,$Y$1,$W$25:$W$221,$Y$2) -> 269878 | C22: =SUMIFS($I$25:$I$221,$V$25:$V$221,$Y$1,$W$25:$W$221,$Y$2) -> 1813 | D22: =SUMIFS($L$25:$L$221,$V$25:$V$221,$Y$1,$W$25:$W$221,$Y$2) -> 1662 | F22: =SUMIFS($P$25:$P$221,$V$25:$V$221,$Y$1,$W$25:$W$221,$Y$2) -> 1153941 | G22: =IF(N(C22)=0,"",B22/C22) -> 148.85714 | I22: =IF(N(D22)=0,"",B22/D22) -> 162.38147 | J22: =IF(N(F22)=0,"",B22/F22) -> 0.23387504
A24: Период / Рекламная кампания | B24: Продукт | C24: Бюджет потрачен, ₽ | D24: Охват | E24: Клики | F24: Всего заказов | G24: Кол-во самовыкупов | H24: CR из клика в заказ % | I24: Заказы от рекламы | J24: CR в заказ % | K24: % выкупа | L24: Выкупы | M24: Цена продажи до СПП | N24: %Скидки СПП | O24: Средний чек, ₽ | P24: Выручка факт, ₽ | Q24: CPO факт, ₽ | R24: Стоимость выкупа факт, ₽ | S24: DRR факт | T24: Выручка план, ₽ | U24: Выполнение плана % | X24: Рейтинг
A25: ▼ ИЮЛЬ 2026 | C25: =C26+C32+C38+C44+C50 -> 27906 | D25: =D26+D32+D38+D44+D50 -> 97351 | F25: =F26+F32+F38+F44+F50 -> 707 | I25: =I26+I32+I38+I44+I50 -> 214 | J25: =IF(N(D25)=0,"",I25/D25) -> 0.0021982311 | K25: =IF(N(I25)=0,"",L25/I25) -> 0.97196262 | L25: =L26+L32+L38+L44+L50 -> 208 | O25: =IF(N(L25)=0,"",P25/L25) -> 675.33173 | P25: =P26+P32+P38+P44+P50 -> 140469 | Q25: =IF(N(I25)=0,"",C25/I25) -> 130.40187 | R25: =IF(N(L25)=0,"",C25/L25) -> 134.16346 | S25: =IF(N(P25)=0,"",C25/P25) -> 0.19866305 | T25: ='Медиаплан'!$K$14 -> 203728 | U25: =IF(N(T25)=0,"",P25/T25) -> 0.68949285
A26: Неделя 1 · 01–07.07 | C26: =SUM(C27:C31) -> 5096 | D26: =SUM(D27:D31) -> 11166 | F26: =SUM(F27:F31) -> 66 | I26: =SUM(I27:I31) -> 40 | J26: =IF(N(D26)=0,"",I26/D26) -> 0.0035823034 | K26: =IF(N(I26)=0,"",L26/I26) -> 0.725 | L26: =SUM(L27:L31) -> 29 | O26: =IF(N(L26)=0,"",P26/L26) -> 722.58621 | P26: =SUM(P27:P31) -> 20955 | Q26: =IF(N(I26)=0,"",C26/I26) -> 127.4 | R26: =IF(N(L26)=0,"",C26/L26) -> 175.72414 | S26: =IF(N(P26)=0,"",C26/P26) -> 0.24318778 | T26: =ROUND('Медиаплан'!$K$14*7/31,0) -> 46003 | U26: =IF(N(T26)=0,"",P26/T26) -> 0.45551377
A27: CPC | B27: Триггер | C27: 2979 | D27: 4364 | F27: 48 | I27: 39 | J27: =IF(N(D27)=0,"",I27/D27) -> 0.0089367553 | K27: 0.7166 | L27: =IF(OR(I27="",K27=""),"",ROUND(I27*K27,0)) -> 28 | O27: 595 | P27: =IF(N(L27)=0,"",L27*O27) -> 16660 | Q27: =IF(N(I27)=0,"",C27/I27) -> 76.384615 | R27: =IF(N(L27)=0,"",C27/L27) -> 106.39286 | S27: =IF(N(P27)=0,"",C27/P27) -> 0.17881152 | V27: Июль | W27: Нед.1
A28: CPM | B28: Триггер | J28: =IF(N(D28)=0,"",I28/D28) | L28: =IF(OR(I28="",K28=""),"",ROUND(I28*K28,0)) | P28: =IF(N(L28)=0,"",L28*O28) | Q28: =IF(N(I28)=0,"",C28/I28) | R28: =IF(N(L28)=0,"",C28/L28) | S28: =IF(N(P28)=0,"",C28/P28) | V28: Июль | W28: Нед.1
A29: CPC | B29: Аппликатор | C29: 120 | D29: 37 | F29: 18 | I29: 1 | J29: =IF(N(D29)=0,"",I29/D29) -> 0.027027027 | K29: 1 | L29: =IF(OR(I29="",K29=""),"",ROUND(I29*K29,0)) -> 1 | O29: 4295 | P29: =IF(N(L29)=0,"",L29*O29) -> 4295 | Q29: =IF(N(I29)=0,"",C29/I29) -> 120 | R29: =IF(N(L29)=0,"",C29/L29) -> 120 | S29: =IF(N(P29)=0,"",C29/P29) -> 0.027939464 | V29: Июль | W29: Нед.1
A30: CPM | B30: Аппликатор | C30: 1997 | D30: 6765 | I30: 0 | J30: =IF(N(D30)=0,"",I30/D30) -> 0 | L30: =IF(OR(I30="",K30=""),"",ROUND(I30*K30,0)) | O30: 4295 | P30: =IF(N(L30)=0,"",L30*O30) | Q30: =IF(N(I30)=0,"",C30/I30) | R30: =IF(N(L30)=0,"",C30/L30) | S30: =IF(N(P30)=0,"",C30/P30) | V30: Июль | W30: Нед.1
J31: =IF(N(D31)=0,"",I31/D31) | L31: =IF(OR(I31="",K31=""),"",ROUND(I31*K31,0)) | P31: =IF(N(L31)=0,"",L31*O31) | Q31: =IF(N(I31)=0,"",C31/I31) | R31: =IF(N(L31)=0,"",C31/L31) | S31: =IF(N(P31)=0,"",C31/P31) | V31: Июль | W31: Нед.1
A32: Неделя 2 · 08–14.07 | C32: =SUM(C33:C37) -> 631 | D32: =SUM(D33:D37) -> 1800 | F32: =SUM(F33:F37) -> 202 | I32: =SUM(I33:I37) -> 10 | J32: =IF(N(D32)=0,"",I32/D32) -> 0.0055555556 | K32: =IF(N(I32)=0,"",L32/I32) -> 0.6 | L32: =SUM(L33:L37) -> 6 | O32: =IF(N(L32)=0,"",P32/L32) -> 595 | P32: =SUM(P33:P37) -> 3570 | Q32: =IF(N(I32)=0,"",C32/I32) -> 63.1 | R32: =IF(N(L32)=0,"",C32/L32) -> 105.16667 | S32: =IF(N(P32)=0,"",C32/P32) -> 0.1767507 | T32: =ROUND('Медиаплан'!$K$14*7/31,0) -> 46003 | U32: =IF(N(T32)=0,"",P32/T32) -> 0.077603635
A33: CPC | B33: Триггер | C33: 462 | D33: 1235 | F33: 198 | I33: 10 | J33: =IF(N(D33)=0,"",I33/D33) -> 0.008097166 | K33: 0.5883 | L33: =IF(OR(I33="",K33=""),"",ROUND(I33*K33,0)) -> 6 | O33: 595 | P33: =IF(N(L33)=0,"",L33*O33) -> 3570 | Q33: =IF(N(I33)=0,"",C33/I33) -> 46.2 | R33: =IF(N(L33)=0,"",C33/L33) -> 77 | S33: =IF(N(P33)=0,"",C33/P33) -> 0.12941176 | V33: Июль | W33: Нед.2
A34: CPM | B34: Триггер | J34: =IF(N(D34)=0,"",I34/D34) | K34: 0.5883 | L34: =IF(OR(I34="",K34=""),"",ROUND(I34*K34,0)) | O34: 595 | P34: =IF(N(L34)=0,"",L34*O34) | Q34: =IF(N(I34)=0,"",C34/I34) | R34: =IF(N(L34)=0,"",C34/L34) | S34: =IF(N(P34)=0,"",C34/P34) | V34: Июль | W34: Нед.2
A35: CPC | B35: Аппликатор | F35: 4 | J35: =IF(N(D35)=0,"",I35/D35) | L35: =IF(OR(I35="",K35=""),"",ROUND(I35*K35,0)) | P35: =IF(N(L35)=0,"",L35*O35) | Q35: =IF(N(I35)=0,"",C35/I35) | R35: =IF(N(L35)=0,"",C35/L35) | S35: =IF(N(P35)=0,"",C35/P35) | V35: Июль | W35: Нед.2
A36: CPM | B36: Аппликатор | C36: 169 | D36: 565 | I36: 0 | J36: =IF(N(D36)=0,"",I36/D36) -> 0 | L36: =IF(OR(I36="",K36=""),"",ROUND(I36*K36,0)) | O36: 4295 | P36: =IF(N(L36)=0,"",L36*O36) | Q36: =IF(N(I36)=0,"",C36/I36) | R36: =IF(N(L36)=0,"",C36/L36) | S36: =IF(N(P36)=0,"",C36/P36) | V36: Июль | W36: Нед.2
J37: =IF(N(D37)=0,"",I37/D37) | L37: =IF(OR(I37="",K37=""),"",ROUND(I37*K37,0)) | P37: =IF(N(L37)=0,"",L37*O37) | Q37: =IF(N(I37)=0,"",C37/I37) | R37: =IF(N(L37)=0,"",C37/L37) | S37: =IF(N(P37)=0,"",C37/P37) | V37: Июль | W37: Нед.2
A38: Неделя 3 · 15–21.07 | C38: =SUM(C39:C43) -> 4084 | D38: =SUM(D39:D43) -> 13884 | F38: =SUM(F39:F43) -> 240 | I38: =SUM(I39:I43) -> 31 | J38: =IF(N(D38)=0,"",I38/D38) -> 0.0022327859 | K38: =IF(N(I38)=0,"",L38/I38) -> 1.6774194 | L38: =SUM(L39:L43) -> 52 | O38: =IF(N(L38)=0,"",P38/L38) -> 666 | P38: =SUM(P39:P43) -> 34632 | Q38: =IF(N(I38)=0,"",C38/I38) -> 131.74194 | R38: =IF(N(L38)=0,"",C38/L38) -> 78.538462 | S38: =IF(N(P38)=0,"",C38/P38) -> 0.11792562 | T38: =ROUND('Медиаплан'!$K$14*7/31,0) -> 46003 | U38: =IF(N(T38)=0,"",P38/T38) -> 0.75282047
A39: CPC | B39: Триггер | C39: 819 | D39: 1821 | F39: 239 | I39: 11 | J39: =IF(N(D39)=0,"",I39/D39) -> 0.006040637 | K39: 1.68 | L39: =IF(OR(I39="",K39=""),"",ROUND(I39*K39,0)) -> 18 | O39: 666 | P39: =IF(N(L39)=0,"",L39*O39) -> 11988 | Q39: =IF(N(I39)=0,"",C39/I39) -> 74.454545 | R39: =IF(N(L39)=0,"",C39/L39) -> 45.5 | S39: =IF(N(P39)=0,"",C39/P39) -> 0.068318318 | V39: Июль | W39: Нед.3
A40: CPM | B40: Триггер | C40: 3190 | D40: 12026 | I40: 20 | J40: =IF(N(D40)=0,"",I40/D40) -> 0.0016630634 | K40: 1.68 | L40: =IF(OR(I40="",K40=""),"",ROUND(I40*K40,0)) -> 34 | O40: 666 | P40: =IF(N(L40)=0,"",L40*O40) -> 22644 | Q40: =IF(N(I40)=0,"",C40/I40) -> 159.5 | R40: =IF(N(L40)=0,"",C40/L40) -> 93.823529 | S40: =IF(N(P40)=0,"",C40/P40) -> 0.14087617 | V40: Июль | W40: Нед.3
A41: CPC | B41: Аппликатор | C41: 75 | D41: 37 | F41: 1 | J41: =IF(N(D41)=0,"",I41/D41) -> 0 | K41: 1 | L41: =IF(OR(I41="",K41=""),"",ROUND(I41*K41,0)) | O41: 4295 | P41: =IF(N(L41)=0,"",L41*O41) | Q41: =IF(N(I41)=0,"",C41/I41) | R41: =IF(N(L41)=0,"",C41/L41) | S41: =IF(N(P41)=0,"",C41/P41) | V41: Июль | W41: Нед.3
A42: CPM | B42: Аппликатор | J42: =IF(N(D42)=0,"",I42/D42) | L42: =IF(OR(I42="",K42=""),"",ROUND(I42*K42,0)) | P42: =IF(N(L42)=0,"",L42*O42) | Q42: =IF(N(I42)=0,"",C42/I42) | R42: =IF(N(L42)=0,"",C42/L42) | S42: =IF(N(P42)=0,"",C42/P42) | V42: Июль | W42: Нед.3
J43: =IF(N(D43)=0,"",I43/D43) | L43: =IF(OR(I43="",K43=""),"",ROUND(I43*K43,0)) | P43: =IF(N(L43)=0,"",L43*O43) | Q43: =IF(N(I43)=0,"",C43/I43) | R43: =IF(N(L43)=0,"",C43/L43) | S43: =IF(N(P43)=0,"",C43/P43) | V43: Июль | W43: Нед.3
...
