Workbook

Sheet Мои блогеры
A1: БАЗА БЛОГЕРОВ — Менеджер 2
A2: Имя блогера — кликабельная ссылка на канал. Ответственный пусто = свободен, можно брать. Стоит «Анна» = уже в работе.
A4: Блогер (ссылка на канал) | B4: Площадка | C4: Источник | D4: Тематика | E4: Подписчики | F4: Ср. охват/просмотры | G4: ER % | H4: Цена (посл.), ₽ | I4: Контакты | J4: Основа промокода | K4: Ответственный | L4: Заметка о работе | M4: Комментарий | N4: Ссылка на канал (URL) | O4: Расчётный CPV, ₽ | P4: Расчётный CPM, ₽
A5: Во саду ли в огороде | B5: YouTube | C5: YouTube-база | D5: Сад-огород | E5: 2110000 | F5: 284882 | G5: 0.0446 | I5: https://www.gosuslugi.ru/snet/67b0da6bb984972032651c5e; https://www.wildberries.ru/catalog/342956246/detail.aspx?targetUrl=EX&utm_source=VoSaduLi&utm_medium=YT&utm_campaign=795299-id-MKSVRassada14.04.26 | J5: VOSADULI | K5: Менеджер 2 | N5: https://www.youtube.com/channel/UCiWA1Ct_IdiUA8a-DTwBj9A
A6: Садовый Гид | B6: YouTube | C6: YouTube-база | D6: Сад-огород | E6: 1840000 | F6: 288127 | G6: 0.0331 | I6: larazara67@mail.ru; https://knd.gov.ru/license?; https://fitstars.ru/subscribe?tariffs%255B%255D=51&utm_source=YouTube&utm_medium=%D0%A1%D0%90%D0%94%D0%9E%D0%92%D0%AB%D0%99%D0%93%D0%98%D0%94%D0%AE%D0%A2%D0%A3%D0%91&utm_campaign=2022&promo=%D0%A1%D0%90%D0%94%D0%9E%D0%92%D0%AB%D0%99 | J6: SADOVYIG | K6: Менеджер 2 | N6: https://www.youtube.com/channel/UCTXMeEml1hhGYagq7QZFqcA
A7: Fishing-Life TVvk | B7: VK | C7: YouTube-база | D7: Рыбалка | E7: 7700 | F7: 30000 | H7: 27500 | K7: Менеджер 2 | L7: договор в работе | N7: https://vkvideo.ru/@fishinglifetv/all | O7: =H7/F7 -> 0.91666667 | P7: =(H7/F7)*1000 -> 916.66667
A8: Fishing-Life TV | B8: YouTube | C8: YouTube-база | D8: Рыбалка | E8: 182000 | F8: 50000 | G8: 0.0256 | H8: 27500 | I8: fishinglifetvsibir@gmail.com | J8: FISHINGL | K8: Менеджер 2 | L8: договор в работе | N8: https://www.youtube.com/channel/UCw4X4WsJHT7UA_XhPONv5VQ | O8: =H8/F8 -> 0.55 | P8: =(H8/F8)*1000 -> 550
A9: Наша Дача | B9: Telegram | C9: Telega.in | D9: Сад-огород | E9: 176000 | G9: 0.0003 | H9: 14266 | I9: https://telega.in/channels/+7oFpKSAGX-s0MTcy/card | J9: NASHADAC | K9: Менеджер 2 | N9: https://t.me/+7oFpKSAGX-s0MTcy
A10: Уютный хуторок | B10: YouTube | C10: YouTube-база | D10: Сад-огород | E10: 176000 | F10: 84181 | G10: 0.0598 | I10: SalniS58@yandex.ru; vk.com/hutorok2025 | J10: UYUTNYIH | K10: Менеджер 2 | N10: https://www.youtube.com/channel/UC8n00W78oxs3zSx33-dC6PQ
A11: Дача | Дом | Огород | B11: Telegram | C11: Telega.in | D11: Сад-огород | E11: 173000 | G11: 0.00029 | H11: 22587 | I11: https://telega.in/channels/+qxekrBe5oJU5ZmIy/card | J11: DACHADOM | K11: Менеджер 2 | N11: https://t.me/+qxekrBe5oJU5ZmIy
A12: Северная рыбалка /Nord fishing | B12: YouTube | C12: YouTube-база | D12: Рыбалка | E12: 119000 | F12: 100000 | G12: 0.064 | H12: 78335 | I12: severnayarybalka@adisom.net; vk.com/club122717706; https://www.ozon.ru/product/zhilet-canadian-camper-fokel-1698137246/?at=RltylDMrRI0nRWVpF0EnV3MTMYnv99i3w8YrqtvljWpG&from_sku=1698146084&oos_search=false; https://www.ozon.ru/product/kurtka-canadian-camper-forkan-1831554104/?at=BrtzmXwVMupolJYQuyAXR0Ys6ApOM2fWO10grSDvNDqp&from_sku=1698094916&oos_search=false | J12: SEVERNAY | K12: Менеджер 2 | L12: отправлено письмо | N12: https://www.youtube.com/channel/UC-wseWH5WqECF0lZhZKxJJA | O12: =H12/F12 -> 0.78335 | P12: =(H12/F12)*1000 -> 783.35
A13: @batya_ilin | B13: YouTube | C13: YouTube-база | D13: Рыбалка | E13: 29600 | F13: 100000 | H13: 38000 | K13: Менеджер 2 | L13: отправлено письмо | N13: https://youtube.com/@batya_ilin | O13: =H13/F13 -> 0.38 | P13: =(H13/F13)*1000 -> 380
A14: novo_fish | B14: TikTok | C14: Tiktok-база | D14: Рыбалка | E14: 7930 | F14: 20000 | H14: 5000 | K14: Менеджер 2 | L14: договор в работе | N14: https://www.tiktok.com/@novo_fish | O14: =H14/F14 -> 0.25 | P14: =(H14/F14)*1000 -> 250
A15: viktorlife24 | B15: TikTok | C15: Tiktok-база | D15: Рыбалка | E15: 33000 | F15: 100000 | H15: 50000 | K15: Менеджер 2 | L15: договор в работе | N15: https://www.tiktok.com/@viktorlife24 | O15: =H15/F15 -> 0.5 | P15: =(H15/F15)*1000 -> 500
A16: viktorlife24youtube | B16: YouTube | C16: YouTube-база | D16: Рыбалка | E16: 6000 | F16: 40000 | H16: 15000 | K16: Менеджер 2 | L16: договор в работе | N16: https://www.youtube.com/@%D0%92%D0%B8%D0%BA%D1%82%D0%BE%D1%80%D0%BF%D1%80%D0%BE%D1%81%D1%82%D0%B0%D0%BD%D0%B8%D1%87%D0%BD%D1%83%D1%8E%D0%B6%D0%B8%D0%B7%D0%BD%D1%8C | O16: =H16/F16 -> 0.375 | P16: =(H16/F16)*1000 -> 375
A17: Хороший день для Рыбалки | B17: YouTube | C17: YouTube-база | D17: Рыбалка | E17: 62700 | F17: 10000 | G17: 0.0244 | H17: 7000 | I17: morfion321@gmail.com; vk.com/id222841731; https://www.donationalerts.com/r/golovinv; https://minoga.ru/?erid=2VtzquxLtyV | J17: HOROSHII | K17: Менеджер 2 | L17: отправлено письмо | N17: https://www.youtube.com/channel/UCppHEwOGz7QvGcXab64tIxQ | O17: =H17/F17 -> 0.7 | P17: =(H17/F17)*1000 -> 700
A18: Сибирский Странник | B18: YouTube | C18: YouTube-база | D18: Рыбалка | E18: 1320000 | F18: 749311 | G18: 0.0488 | I18: RUS151083@mail.ru; vk.com/id52521280; vk.com/alekssibirskiy; https://www.wildberries.ru/seller/250090340 | J18: SIBIRSKI | K18: Менеджер 2 | L18: сказал что подумает | N18: https://www.youtube.com/channel/UCgkes8es2x4yoEmLTGpMjEA | O18: =H18/F18 -> 0 | P18: =(H18/F18)*1000 -> 0
A19: PETROVCHANKA LERA | B19: YouTube | C19: YouTube-база | D19: Сад-огород | E19: 1220000 | F19: 1184993 | G19: 0.0325 | I19: @petrovchanka_lera; https://knd.gov.ru/license? | J19: PETROVCH | K19: Менеджер 2 | N19: https://www.youtube.com/channel/UCqJUOdRU1eFDk02BYxbWRnw
A20: AssistanceTV | B20: YouTube | C20: YouTube-база | D20: Рыбалка | E20: 1060000 | F20: 151971 | G20: 0.0311 | I20: serggioq21@gmail.com | J20: ASSISTAN | K20: Менеджер 2 | L20: украина | N20: https://www.youtube.com/channel/UC53tGQacLCKgMoViyQJTA_g | O20: =H20/F20 -> 0 | P20: =(H20/F20)*1000 -> 0
A21: Снасти здрасьте! | B21: YouTube | C21: YouTube-база | D21: Рыбалка | E21: 945000 | F21: 408588 | G21: 0.0342 | I21: Snastizdraste@yandex.ru | J21: SNASTIZD | K21: Менеджер 2 | L21: отправлено письмо | N21: https://www.youtube.com/channel/UCfkn7KM1LBAxxAq7r034a1w | O21: =H21/F21 -> 0 | P21: =(H21/F21)*1000 -> 0
A22: Тепличный бизнес в деревне! | B22: YouTube | C22: YouTube-база | D22: Сад-огород | E22: 938000 | F22: 188314 | G22: 0.0606 | I22: @yakov_ogorodnik; vk.com/public175441970; vk.com/id521874877; https://yakovogorodnik.ru; https://yakovogorodnik.ru/education | J22: TEPLICHN | K22: Менеджер 2 | N22: https://www.youtube.com/channel/UCqL7Y7jcVarKAxI45yjdfnw
A23: Сад-огород! LIFE | B23: YouTube | C23: YouTube-база | D23: Сад-огород | E23: 884000 | F23: 66164 | G23: 0.0175 | I23: https://max.ru/ch_62af5280dda22178b423a5d8 | J23: SADOGORO | K23: Менеджер 2 | N23: https://www.youtube.com/channel/UCpDmoTV4_8FRuiLVqlpa1ww
A24: Вероника Поливкина | B24: YouTube | C24: YouTube-база | D24: Сад-огород | E24: 814000 | F24: 65479 | G24: 0.0453 | I24: @veronika_polivkina; vk.com/club211638113; https://gosuslugi.ru/snet/67af2e74a7b872052aa3f19c; https://wibes.ru/author/1079485 | J24: VERONIKA | K24: Менеджер 2 | N24: https://www.youtube.com/channel/UC_zKdhty-DNqhnySR9FcVWg
A25: Голова садовая | B25: YouTube | C25: YouTube-база | D25: Сад-огород | E25: 770000 | F25: 73265 | G25: 0.0282 | I25: afontovo-tv@mail.ru; @golovasadova | J25: GOLOVASA | K25: Менеджер 2 | N25: https://www.youtube.com/channel/UCZP-t7tMmA-_hXpL90L3WBw
A26: СУПЕР - ОТПУСК на ДАЧЕ | B26: YouTube | C26: YouTube-база | D26: Сад-огород | E26: 714000 | F26: 129402 | G26: 0.056 | H26: 300 | I26: @garden_ramenskoe; vk.com/superotpusknadache; vk.com/garden_ram; https://knd.gov.ru/license?; https://bit.ly/484Z1aJ | J26: SUPEROTP | K26: Менеджер 2 | N26: https://www.youtube.com/channel/UCDbkx0Ci91M09HjQxzU9yuw
A27: ГЕНЕРАЛЬСКИЙ САД | B27: YouTube | C27: YouTube-база | D27: Сад-огород | E27: 675000 | F27: 214572 | G27: 0.0108 | I27: yrojaysad@gmail.com | J27: GENERALS | K27: Менеджер 2 | N27: https://www.youtube.com/channel/UCHQQ4wAhue1Tx46_IvzNOMQ
A28: Огород - сад Медведевых | B28: YouTube | C28: YouTube-база | D28: Сад-огород | E28: 581000 | F28: 81343 | G28: 0.0706 | I28: tomatoved@mail.ru; @ogorodsadmedvedevykh; vk.com/svoitomaty; https://svoisemena.ru; https://svoisemena.ru/pelargonii | J28: OGORODSA | K28: Менеджер 2 | N28: https://www.youtube.com/channel/UC7oAhM5FWIUgOzHZ8oXDQqQ
A29: КРУГОВОРОТ_ДАЧА_ОГОРОД | B29: YouTube | C29: YouTube-база | D29: Сад-огород | E29: 513000 | F29: 171767 | G29: 0.0372 | I29: -buba22438@gmail.com; @krugovorottdo | J29: KRUGOVOR | K29: Менеджер 2 | N29: https://www.youtube.com/channel/UCVyq0UBgM60QB434-iaDTVg
A30: Моя дача | B30: Telegram | C30: Telega.in | D30: Сад-огород | E30: 471000 | G30: 0.00027 | H30: 34965 | I30: https://telega.in/channels/mydaca/card | J30: MOYADACH | K30: Менеджер 2 | N30: https://t.me/mydaca
A31: Просто Марина | B31: YouTube | C31: YouTube-база | D31: Сад-огород | E31: 431000 | F31: 83052 | G31: 0.0471 | I31: alt-marina@yandex.ru; https://knd.gov.ru/license?; https://ydolv.mobz.click/umrkl3 | J31: PROSTOMA | K31: Менеджер 2 | N31: https://www.youtube.com/channel/UCFkoPqrepBhhmfKzClA-r_w
A32: ОРЗ ТВ - Охотники и Рыболовы ЗАПОЛЯРЬЯ | B32: YouTube | C32: YouTube-база | D32: Рыбалка | E32: 171000 | F32: 25000 | G32: 0.0504 | H32: 35000 | I32: orztv@themakers.ru; https://clck.ru/F4QLL; https://clck.ru/F4QKx | J32: ORZTVOHO | K32: Менеджер 2 | L32: отправлено письмо | N32: https://www.youtube.com/channel/UC6_SwzIMfPfWotQyRqWIKiQ | O32: =H32/F32 -> 1.4 | P32: =(H32/F32)*1000 -> 1400
A33: https://vk.ru/ohotnikinao | B33: VK | C33: Vkontakte-база | D33: Рыбалка | E33: 7500 | F33: 7000 | H33: 0 | K33: Менеджер 2 | N33: https://vk.ru/ohotnikinao | O33: =H33/F33 -> 0 | P33: =(H33/F33)*1000 -> 0
A34: АГАТ | B34: YouTube | C34: YouTube-база | D34: Рыбалка | E34: 408000 | F34: 360256 | G34: 0.049 | H34: 10000 | I34: agat017@yandex.ru | J34: AGAT | K34: Менеджер 2 | L34: отправлено письмо | N34: https://www.youtube.com/channel/UC8X_Ri3NBTXCoSNpOfgX82g | O34: =H34/F34 -> 0.027758039 | P34: =(H34/F34)*1000 -> 27.758039
A35: Волшебная грядка Марины Шевляковой | B35: YouTube | C35: YouTube-база | D35: Сад-огород | E35: 379000 | F35: 62039 | G35: 0.0333 | I35: marasja@gmail.com; @volshebnayagryadka; vk.com/volshebnaya_gryadka; https://gosuslugi.ru/snet/67b4a2d08c08d3723f2f3832; https://clck.ru/3TDmmp | J35: VOLSHEBN | K35: Менеджер 2 | N35: https://www.youtube.com/channel/UCbODBVkNzh3Ny23-m7X5s4w
A36: Татьяна Башмакова - Ваша Дача (vashadacha) | B36: YouTube | C36: YouTube-база | D36: Сад-огород | E36: 363000 | F36: 41670 | G36: 0.0696 | I36: vk.com/best_dacha | J36: TATYANAB | K36: Менеджер 2 | N36: https://www.youtube.com/channel/UCK_1NtbyzOK3w_ARLqNiWbg
A37: Алёнин сад | B37: YouTube | C37: YouTube-база | D37: Сад-огород | E37: 335000 | F37: 41378 | G37: 0.0601 | I37: @aleninsad; vk.com/aleninsad; http://www.aleninsad.com; https://web.max.ru/-68671270868407 | J37: ALENINSA | K37: Менеджер 2 | N37: https://www.youtube.com/channel/UCnJXX-FozHVLpLTeumHCrWQ
A38: Дача мечты | B38: Telegram | C38: Telega.in | D38: Сад-огород | E38: 333000 | G38: 0.00026 | H38: 30769 | I38: https://telega.in/channels/+D03xUB3vKRYyNDk6/card | J38: DACHAMEC | K38: Менеджер 2 | N38: https://t.me/+D03xUB3vKRYyNDk6
A39: Земеля | B39: YouTube | C39: YouTube-база | D39: Рыбалка | E39: 246000 | F39: 347154 | G39: 0.0532 | J39: ZEMELYA | K39: Менеджер 2 | L39: отправлено письмо в вк | N39: https://www.youtube.com/channel/UC1XrVpIJKHZUD9OCm9mDh8A | O39: =H39/F39 -> 0 | P39: =(H39/F39)*1000 -> 0
A40: Павел Про TV | B40: YouTube | C40: YouTube-база | D40: Рыбалка | E40: 319000 | F40: 219926 | G40: 0.061 | I40: vk.com/id366371122; @pavelprotv; altfishing-club.ru/user/755-pavel-pro | J40: PAVELPRO | K40: Менеджер 2 | L40: не подходит | N40: https://www.youtube.com/channel/UCjD01pt7Oic6hJg-h0NVihQ | O40: =H40/F40 -> 0 | P40: =(H40/F40)*1000 -> 0
A41: Клёвая рыбалка / Hot fishing | B41: YouTube | C41: YouTube-база | D41: Рыбалка | E41: 613000 | F41: 242206 | G41: 0.0507 | I41: vk.com/coolhotfishing; https://клеваярыбалка.рф; https://hot-fishing.com | J41: KLEVAYAR | K41: Менеджер 2 | L41: не подходит | N41: https://www.youtube.com/channel/UCaRJiAXxS3j2dEz0FLIjEGg | O41: =H41/F41 -> 0 | P41: =(H41/F41)*1000 -> 0
...

Sheet Медиаплан
A1: МЕДИАПЛАН — Триггер (прикормки для рыб)
A2: Синее — задаёт руководитель (бюджет, цель). Жёлтое — заполняет менеджер (охват, CTR, CR, чек, % выкупа). Серое — считается формулами.
A6: ▼ АВГУСТ 2026
A7: Бюджет на месяц, ₽ | B7: =3154950/2 -> 1577475 | D7: Целевой DRR | E7: 0.13
A8: Канал | B8: Бюджет, ₽ | C8: Прогноз CPV, ₽ | D8: Прогноз охвата | E8: CTR % | F8: Клики | G8: CR в заказ % | H8: Заказы | I8: CPO, ₽ | J8: Выкупы | K8: Стоимость выкупа, ₽ | L8: Выручка, ₽ | M8: DRR
A9: МАРКЕТПЛЕЙС (ВБ / Ozon) | G9: Ср. чек, ₽ | H9: 600 | J9: % выкупа | K9: 0.95 | M9: 0.18
A10: Telegram | B10: 200000 | C10: 0.57 | D10: =IF(OR(B10="",C10=""),"",ROUND(B10/C10,0)) -> 350877 | E10: 0.0082 | F10: =IF(OR(D10="",E10=""),"",ROUND(D10*E10,0)) -> 2877 | G10: 0.17 | H10: =IF(OR(F10="",G10=""),"",ROUND(F10*G10,0)) -> 489 | I10: =IF(N(H10)=0,"",ROUND(B10/H10,0)) -> 409 | J10: =IF(OR(N(H10)=0,$K$9=""),"",ROUND(H10*$K$9,0)) -> 465 | K10: =IF(N(J10)=0,"",ROUND(B10/J10,0)) -> 430 | L10: =IF(N(J10)=0,"",ROUND(J10*$H$9,0)) -> 279000 | M10: =IF(N(L10)=0,"",B10/L10) -> 0.71684588
A11: MAX | B11: 283000 | C11: 0.71 | D11: =IF(OR(B11="",C11=""),"",ROUND(B11/C11,0)) -> 398592 | E11: 0.021 | F11: =IF(OR(D11="",E11=""),"",ROUND(D11*E11,0)) -> 8370 | G11: 0.23 | H11: =IF(OR(F11="",G11=""),"",ROUND(F11*G11,0)) -> 1925 | I11: =IF(N(H11)=0,"",ROUND(B11/H11,0)) -> 147 | J11: =IF(OR(N(H11)=0,$K$9=""),"",ROUND(H11*$K$9,0)) -> 1829 | K11: =IF(N(J11)=0,"",ROUND(B11/J11,0)) -> 155 | L11: =IF(N(J11)=0,"",ROUND(J11*$H$9,0)) -> 1097400 | M11: =IF(N(L11)=0,"",B11/L11) -> 0.25788227
A12: VK | B12: 274000 | C12: 0.72 | D12: =IF(OR(B12="",C12=""),"",ROUND(B12/C12,0)) -> 380556 | E12: 0.012 | F12: =IF(OR(D12="",E12=""),"",ROUND(D12*E12,0)) -> 4567 | G12: 0.23 | H12: =IF(OR(F12="",G12=""),"",ROUND(F12*G12,0)) -> 1050 | I12: =IF(N(H12)=0,"",ROUND(B12/H12,0)) -> 261 | J12: =IF(OR(N(H12)=0,$K$9=""),"",ROUND(H12*$K$9,0)) -> 998 | K12: =IF(N(J12)=0,"",ROUND(B12/J12,0)) -> 275 | L12: =IF(N(J12)=0,"",ROUND(J12*$H$9,0)) -> 598800 | M12: =IF(N(L12)=0,"",B12/L12) -> 0.45758183
A13: YouTube | B13: 400000 | C13: 0.35 | D13: =IF(OR(B13="",C13=""),"",ROUND(B13/C13,0)) -> 1142857 | E13: 0.006 | F13: =IF(OR(D13="",E13=""),"",ROUND(D13*E13,0)) -> 6857 | G13: 0.23 | H13: =IF(OR(F13="",G13=""),"",ROUND(F13*G13,0)) -> 1577 | I13: =IF(N(H13)=0,"",ROUND(B13/H13,0)) -> 254 | J13: =IF(OR(N(H13)=0,$K$9=""),"",ROUND(H13*$K$9,0)) -> 1498 | K13: =IF(N(J13)=0,"",ROUND(B13/J13,0)) -> 267 | L13: =IF(N(J13)=0,"",ROUND(J13*$H$9,0)) -> 898800 | M13: =IF(N(L13)=0,"",B13/L13) -> 0.44503783
A14: TikTok | B14: 150000 | C14: 0.8 | D14: =IF(OR(B14="",C14=""),"",ROUND(B14/C14,0)) -> 187500 | E14: 0.01 | F14: =IF(OR(D14="",E14=""),"",ROUND(D14*E14,0)) -> 1875 | G14: 0.23 | H14: =IF(OR(F14="",G14=""),"",ROUND(F14*G14,0)) -> 431 | I14: =IF(N(H14)=0,"",ROUND(B14/H14,0)) -> 348 | J14: =IF(OR(N(H14)=0,$K$9=""),"",ROUND(H14*$K$9,0)) -> 409 | K14: =IF(N(J14)=0,"",ROUND(B14/J14,0)) -> 367 | L14: =IF(N(J14)=0,"",ROUND(J14*$H$9,0)) -> 245400 | M14: =IF(N(L14)=0,"",B14/L14) -> 0.61124694
A15: Rutube | D15: =IF(OR(B15="",C15=""),"",ROUND(B15/C15,0)) | F15: =IF(OR(D15="",E15=""),"",ROUND(D15*E15,0)) | H15: =IF(OR(F15="",G15=""),"",ROUND(F15*G15,0)) | I15: =IF(N(H15)=0,"",ROUND(B15/H15,0)) | J15: =IF(OR(N(H15)=0,$K$9=""),"",ROUND(H15*$K$9,0)) | K15: =IF(N(J15)=0,"",ROUND(B15/J15,0)) | L15: =IF(N(J15)=0,"",ROUND(J15*$H$9,0)) | M15: =IF(N(L15)=0,"",B15/L15)
A16: Instagram | D16: =IF(OR(B16="",C16=""),"",ROUND(B16/C16,0)) | F16: =IF(OR(D16="",E16=""),"",ROUND(D16*E16,0)) | H16: =IF(OR(F16="",G16=""),"",ROUND(F16*G16,0)) | I16: =IF(N(H16)=0,"",ROUND(B16/H16,0)) | J16: =IF(OR(N(H16)=0,$K$9=""),"",ROUND(H16*$K$9,0)) | K16: =IF(N(J16)=0,"",ROUND(B16/J16,0)) | L16: =IF(N(J16)=0,"",ROUND(J16*$H$9,0)) | M16: =IF(N(L16)=0,"",B16/L16)
A17: ИТОГО — МП | B17: =SUM(B10:B16) -> 1307000 | C17: =IF(N(D17)=0,"",ROUND(B17/D17,2)) -> 0.53 | D17: =SUM(D10:D16) -> 2460382 | F17: =SUM(F10:F16) -> 24546 | H17: =SUM(H10:H16) -> 5472 | I17: =IF(N(H17)=0,"",ROUND(B17/H17,0)) -> 239 | J17: =SUM(J10:J16) -> 5199 | K17: =IF(N(J17)=0,"",ROUND(B17/J17,0)) -> 251 | L17: =SUM(L10:L16) -> 3119400 | M17: =IF(N(L17)=0,"",B17/L17) -> 0.41899083
A18: САЙТ | G18: Ср. чек, ₽ | H18: 1180 | J18: % выкупа | K18: 0.95
A19: Telegram | B19: 40000 | C19: 0.57 | D19: =IF(OR(B19="",C19=""),"",ROUND(B19/C19,0)) -> 70175 | E19: 0.0082 | F19: =IF(OR(D19="",E19=""),"",ROUND(D19*E19,0)) -> 575 | G19: 0.08 | H19: =IF(OR(F19="",G19=""),"",ROUND(F19*G19,0)) -> 46 | I19: =IF(N(H19)=0,"",ROUND(B19/H19,0)) -> 870 | J19: =IF(OR(N(H19)=0,$K$18=""),"",ROUND(H19*$K$18,0)) -> 44 | K19: =IF(N(J19)=0,"",ROUND(B19/J19,0)) -> 909 | L19: =IF(N(J19)=0,"",ROUND(J19*$H$18,0)) -> 51920 | M19: =IF(N(L19)=0,"",B19/L19) -> 0.77041602
A20: MAX | B20: 50475 | C20: 0.71 | D20: =IF(OR(B20="",C20=""),"",ROUND(B20/C20,0)) -> 71092 | E20: 0.021 | F20: =IF(OR(D20="",E20=""),"",ROUND(D20*E20,0)) -> 1493 | G20: 0.11 | H20: =IF(OR(F20="",G20=""),"",ROUND(F20*G20,0)) -> 164 | I20: =IF(N(H20)=0,"",ROUND(B20/H20,0)) -> 308 | J20: =IF(OR(N(H20)=0,$K$18=""),"",ROUND(H20*$K$18,0)) -> 156 | K20: =IF(N(J20)=0,"",ROUND(B20/J20,0)) -> 324 | L20: =IF(N(J20)=0,"",ROUND(J20*$H$18,0)) -> 184080 | M20: =IF(N(L20)=0,"",B20/L20) -> 0.27420143
A21: VK | B21: 30000 | C21: 0.72 | D21: =IF(OR(B21="",C21=""),"",ROUND(B21/C21,0)) -> 41667 | E21: 0.012 | F21: =IF(OR(D21="",E21=""),"",ROUND(D21*E21,0)) -> 500 | G21: 0.11 | H21: =IF(OR(F21="",G21=""),"",ROUND(F21*G21,0)) -> 55 | I21: =IF(N(H21)=0,"",ROUND(B21/H21,0)) -> 545 | J21: =IF(OR(N(H21)=0,$K$18=""),"",ROUND(H21*$K$18,0)) -> 52 | K21: =IF(N(J21)=0,"",ROUND(B21/J21,0)) -> 577 | L21: =IF(N(J21)=0,"",ROUND(J21*$H$18,0)) -> 61360 | M21: =IF(N(L21)=0,"",B21/L21) -> 0.48891786
A22: YouTube | B22: 100000 | C22: 0.35 | D22: =IF(OR(B22="",C22=""),"",ROUND(B22/C22,0)) -> 285714 | E22: 0.006 | F22: =IF(OR(D22="",E22=""),"",ROUND(D22*E22,0)) -> 1714 | G22: 0.11 | H22: =IF(OR(F22="",G22=""),"",ROUND(F22*G22,0)) -> 189 | I22: =IF(N(H22)=0,"",ROUND(B22/H22,0)) -> 529 | J22: =IF(OR(N(H22)=0,$K$18=""),"",ROUND(H22*$K$18,0)) -> 180 | K22: =IF(N(J22)=0,"",ROUND(B22/J22,0)) -> 556 | L22: =IF(N(J22)=0,"",ROUND(J22*$H$18,0)) -> 212400 | M22: =IF(N(L22)=0,"",B22/L22) -> 0.47080979
A23: TikTok | B23: 50000 | C23: 0.8 | D23: =IF(OR(B23="",C23=""),"",ROUND(B23/C23,0)) -> 62500 | E23: 0.01 | F23: =IF(OR(D23="",E23=""),"",ROUND(D23*E23,0)) -> 625 | G23: 0.11 | H23: =IF(OR(F23="",G23=""),"",ROUND(F23*G23,0)) -> 69 | I23: =IF(N(H23)=0,"",ROUND(B23/H23,0)) -> 725 | J23: =IF(OR(N(H23)=0,$K$18=""),"",ROUND(H23*$K$18,0)) -> 66 | K23: =IF(N(J23)=0,"",ROUND(B23/J23,0)) -> 758 | L23: =IF(N(J23)=0,"",ROUND(J23*$H$18,0)) -> 77880 | M23: =IF(N(L23)=0,"",B23/L23) -> 0.64201335
A24: Rutube | D24: =IF(OR(B24="",C24=""),"",ROUND(B24/C24,0)) | F24: =IF(OR(D24="",E24=""),"",ROUND(D24*E24,0)) | H24: =IF(OR(F24="",G24=""),"",ROUND(F24*G24,0)) | I24: =IF(N(H24)=0,"",ROUND(B24/H24,0)) | J24: =IF(OR(N(H24)=0,$K$18=""),"",ROUND(H24*$K$18,0)) | K24: =IF(N(J24)=0,"",ROUND(B24/J24,0)) | L24: =IF(N(J24)=0,"",ROUND(J24*$H$18,0)) | M24: =IF(N(L24)=0,"",B24/L24)
A25: Instagram | D25: =IF(OR(B25="",C25=""),"",ROUND(B25/C25,0)) | F25: =IF(OR(D25="",E25=""),"",ROUND(D25*E25,0)) | H25: =IF(OR(F25="",G25=""),"",ROUND(F25*G25,0)) | I25: =IF(N(H25)=0,"",ROUND(B25/H25,0)) | J25: =IF(OR(N(H25)=0,$K$18=""),"",ROUND(H25*$K$18,0)) | K25: =IF(N(J25)=0,"",ROUND(B25/J25,0)) | L25: =IF(N(J25)=0,"",ROUND(J25*$H$18,0)) | M25: =IF(N(L25)=0,"",B25/L25)
A26: ИТОГО — Сайт | B26: =SUM(B19:B25) -> 270475 | C26: =IF(N(D26)=0,"",ROUND(B26/D26,2)) -> 0.51 | D26: =SUM(D19:D25) -> 531148 | F26: =SUM(F19:F25) -> 4907 | H26: =SUM(H19:H25) -> 523 | I26: =IF(N(H26)=0,"",ROUND(B26/H26,0)) -> 517 | J26: =SUM(J19:J25) -> 498 | K26: =IF(N(J26)=0,"",ROUND(B26/J26,0)) -> 543 | L26: =SUM(L19:L25) -> 587640 | M26: =IF(N(L26)=0,"",B26/L26) -> 0.4602733
A27: ИТОГО ЗА МЕСЯЦ (МП + Сайт) | B27: =B17+B26 -> 1577475 | C27: =IF(N(D27)=0,"",ROUND(B27/D27,2)) -> 0.53 | D27: =D17+D26 -> 2991530 | F27: =F17+F26 -> 29453 | H27: =H17+H26 -> 5995 | I27: =IF(N(H27)=0,"",ROUND(B27/H27,0)) -> 263 | J27: =J17+J26 -> 5697 | K27: =IF(N(J27)=0,"",ROUND(B27/J27,0)) -> 277 | L27: =L17+L26 -> 3707040 | M27: =IF(N(L27)=0,"",B27/L27) -> 0.42553493
A28: Вердикт по DRR | B28: =IF(OR(N(L27)=0,N($E$7)=0),"Заполни бюджет, CPV и параметры",IF(M27<=$E$7,"В ЦЕЛЬ: DRR "&ROUND(M27*100,1)&"% при цели "&ROUND($E$7*100,1)&"%","ВЫШЕ ЦЕЛИ: DRR "&ROUND(M27*100,1)&"% при цели "&ROUND($E$7*100,1)&"%")) -> ВЫШЕ ЦЕЛИ: DRR 42,6% при цели 13%
A30: ▼ Сентябрь 2026 | B30: AT
A31: Бюджет на месяц, ₽ | B31: 660000 | D31: Целевой DRR | E31: 0.13
A32: Канал | B32: Бюджет, ₽ | C32: Прогноз CPV, ₽ | D32: Прогноз охвата | E32: CTR % | F32: Клики | G32: CR в заказ % | H32: Заказы | I32: CPO, ₽ | J32: Выкупы | K32: Стоимость выкупа, ₽ | L32: Выручка, ₽ | M32: DRR
A33: МАРКЕТПЛЕЙС (ВБ / Ozon) | G33: Ср. чек, ₽ | H33: 748 | J33: % выкупа | K33: 0.95 | M33: 0.18
A34: Telegram | B34: 31000 | C34: 0.8 | D34: =IF(OR(B34="",C34=""),"",ROUND(B34/C34,0)) -> 38750 | E34: 0.0082 | F34: =IF(OR(D34="",E34=""),"",ROUND(D34*E34,0)) -> 318 | G34: 0.17 | H34: =IF(OR(F34="",G34=""),"",ROUND(F34*G34,0)) -> 54 | I34: =IF(N(H34)=0,"",ROUND(B34/H34,0)) -> 574 | J34: =IF(OR(N(H34)=0,$K$9=""),"",ROUND(H34*$K$9,0)) -> 51 | K34: =IF(N(J34)=0,"",ROUND(B34/J34,0)) -> 608 | L34: =IF(N(J34)=0,"",ROUND(J34*$H$9,0)) -> 30600 | M34: =IF(N(L34)=0,"",B34/L34) -> 1.0130719
A35: MAX | B35: 63000 | C35: 0.9 | D35: =IF(OR(B35="",C35=""),"",ROUND(B35/C35,0)) -> 70000 | E35: 0.021 | F35: =IF(OR(D35="",E35=""),"",ROUND(D35*E35,0)) -> 1470 | G35: 0.23 | H35: =IF(OR(F35="",G35=""),"",ROUND(F35*G35,0)) -> 338 | I35: =IF(N(H35)=0,"",ROUND(B35/H35,0)) -> 186 | J35: =IF(OR(N(H35)=0,$K$9=""),"",ROUND(H35*$K$9,0)) -> 321 | K35: =IF(N(J35)=0,"",ROUND(B35/J35,0)) -> 196 | L35: =IF(N(J35)=0,"",ROUND(J35*$H$9,0)) -> 192600 | M35: =IF(N(L35)=0,"",B35/L35) -> 0.3271028
A36: VK | B36: 119000 | C36: 0.72 | D36: =IF(OR(B36="",C36=""),"",ROUND(B36/C36,0)) -> 165278 | E36: 0.012 | F36: =IF(OR(D36="",E36=""),"",ROUND(D36*E36,0)) -> 1983 | G36: 0.23 | H36: =IF(OR(F36="",G36=""),"",ROUND(F36*G36,0)) -> 456 | I36: =IF(N(H36)=0,"",ROUND(B36/H36,0)) -> 261 | J36: =IF(OR(N(H36)=0,$K$9=""),"",ROUND(H36*$K$9,0)) -> 433 | K36: =IF(N(J36)=0,"",ROUND(B36/J36,0)) -> 275 | L36: =IF(N(J36)=0,"",ROUND(J36*$H$9,0)) -> 259800 | M36: =IF(N(L36)=0,"",B36/L36) -> 0.45804465
A37: YouTube | B37: 200000 | C37: 0.6 | D37: =IF(OR(B37="",C37=""),"",ROUND(B37/C37,0)) -> 333333 | E37: 0.006 | F37: =IF(OR(D37="",E37=""),"",ROUND(D37*E37,0)) -> 2000 | G37: 0.23 | H37: =IF(OR(F37="",G37=""),"",ROUND(F37*G37,0)) -> 460 | I37: =IF(N(H37)=0,"",ROUND(B37/H37,0)) -> 435 | J37: =IF(OR(N(H37)=0,$K$9=""),"",ROUND(H37*$K$9,0)) -> 437 | K37: =IF(N(J37)=0,"",ROUND(B37/J37,0)) -> 458 | L37: =IF(N(J37)=0,"",ROUND(J37*$H$9,0)) -> 262200 | M37: =IF(N(L37)=0,"",B37/L37) -> 0.76277651
A38: TikTok | B38: 217000 | C38: 0.8 | D38: =IF(OR(B38="",C38=""),"",ROUND(B38/C38,0)) -> 271250 | E38: 0.01 | F38: =IF(OR(D38="",E38=""),"",ROUND(D38*E38,0)) -> 2713 | G38: 0.23 | H38: =IF(OR(F38="",G38=""),"",ROUND(F38*G38,0)) -> 624 | I38: =IF(N(H38)=0,"",ROUND(B38/H38,0)) -> 348 | J38: =IF(OR(N(H38)=0,$K$9=""),"",ROUND(H38*$K$9,0)) -> 593 | K38: =IF(N(J38)=0,"",ROUND(B38/J38,0)) -> 366 | L38: =IF(N(J38)=0,"",ROUND(J38*$H$9,0)) -> 355800 | M38: =IF(N(L38)=0,"",B38/L38) -> 0.6098932
A39: Rutube | D39: =IF(OR(B39="",C39=""),"",ROUND(B39/C39,0)) | F39: =IF(OR(D39="",E39=""),"",ROUND(D39*E39,0)) | H39: =IF(OR(F39="",G39=""),"",ROUND(F39*G39,0)) | I39: =IF(N(H39)=0,"",ROUND(B39/H39,0)) | J39: =IF(OR(N(H39)=0,$K$9=""),"",ROUND(H39*$K$9,0)) | K39: =IF(N(J39)=0,"",ROUND(B39/J39,0)) | L39: =IF(N(J39)=0,"",ROUND(J39*$H$9,0)) | M39: =IF(N(L39)=0,"",B39/L39)
A40: Instagram | D40: =IF(OR(B40="",C40=""),"",ROUND(B40/C40,0)) | F40: =IF(OR(D40="",E40=""),"",ROUND(D40*E40,0)) | H40: =IF(OR(F40="",G40=""),"",ROUND(F40*G40,0)) | I40: =IF(N(H40)=0,"",ROUND(B40/H40,0)) | J40: =IF(OR(N(H40)=0,$K$9=""),"",ROUND(H40*$K$9,0)) | K40: =IF(N(J40)=0,"",ROUND(B40/J40,0)) | L40: =IF(N(J40)=0,"",ROUND(J40*$H$9,0)) | M40: =IF(N(L40)=0,"",B40/L40)
A41: ИТОГО — МП | B41: =SUM(B34:B40) -> 630000 | C41: =IF(N(D41)=0,"",ROUND(B41/D41,2)) -> 0.72 | D41: =SUM(D34:D40) -> 878611 | F41: =SUM(F34:F40) -> 8484 | H41: =SUM(H34:H40) -> 1932 | I41: =IF(N(H41)=0,"",ROUND(B41/H41,0)) -> 326 | J41: =SUM(J34:J40) -> 1835 | K41: =IF(N(J41)=0,"",ROUND(B41/J41,0)) -> 343 | L41: =SUM(L34:L40) -> 1101000 | M41: =IF(N(L41)=0,"",B41/L41) -> 0.57220708
A42: САЙТ | G42: Ср. чек, ₽ | H42: 1180 | J42: % выкупа | K42: 0.95
A43: Telegram | B43: 10000 | C43: 0.8 | D43: =IF(OR(B43="",C43=""),"",ROUND(B43/C43,0)) -> 12500 | E43: 0.0082 | F43: =IF(OR(D43="",E43=""),"",ROUND(D43*E43,0)) -> 103 | G43: 0.08 | H43: =IF(OR(F43="",G43=""),"",ROUND(F43*G43,0)) -> 8 | I43: =IF(N(H43)=0,"",ROUND(B43/H43,0)) -> 1250 | J43: =IF(OR(N(H43)=0,$K$18=""),"",ROUND(H43*$K$18,0)) -> 8 | K43: =IF(N(J43)=0,"",ROUND(B43/J43,0)) -> 1250 | L43: =IF(N(J43)=0,"",ROUND(J43*$H$18,0)) -> 9440 | M43: =IF(N(L43)=0,"",B43/L43) -> 1.059322
A44: MAX | B44: 20000 | C44: 0.9 | D44: =IF(OR(B44="",C44=""),"",ROUND(B44/C44,0)) -> 22222 | E44: 0.021 | F44: =IF(OR(D44="",E44=""),"",ROUND(D44*E44,0)) -> 467 | G44: 0.11 | H44: =IF(OR(F44="",G44=""),"",ROUND(F44*G44,0)) -> 51 | I44: =IF(N(H44)=0,"",ROUND(B44/H44,0)) -> 392 | J44: =IF(OR(N(H44)=0,$K$18=""),"",ROUND(H44*$K$18,0)) -> 48 | K44: =IF(N(J44)=0,"",ROUND(B44/J44,0)) -> 417 | L44: =IF(N(J44)=0,"",ROUND(J44*$H$18,0)) -> 56640 | M44: =IF(N(L44)=0,"",B44/L44) -> 0.35310734
...

Sheet Август
A1: не
A2: Выбери блогера в колонке A — ссылка, подписчики, площадка, промокод, стоимость подтянутся. «🔗 открыть» ведёт на канал.
A3: Выкупы = Заказы × %выкупа. Выручка = Средний чек × Выкупы. CAC/CPO по факту.
A5: Блогер | B5: Ссылка на канал | C5: Подписчики | D5: Площадка | E5: Канал продаж | F5: № договора | G5: Сценарий рекламы | H5: Дата выхода | I5: Статус | J5: Стоимость размещения | K5: Налог | L5: Себестоимость продукции | M5: Итого к оплате | N5: Код маркировки (ERID) | O5: Ссылка с UTM | P5: Ссылка Мобзио | Q5: Промокод | R5: Подменный артикул | S5: Ссылка на размещение | T5: Право использования | U5: Охват | V5: CPV, ₽ | W5: Клики WB/ сайт | X5: Клики мобзио | Y5: Цена за клик, ₽ | Z5: Корзины | AA5: Заказы | AB5: Сумма заказов, ₽ | AC5: % выкупа | AD5: Выкупы | AE5: Средний чек, ₽ | AF5: Выручка от выкупов, ₽ | AG5: Стоимость выкупа, ₽ | AH5: CPO, ₽ | AI5: Продукт | AJ5: Комментарий
A6: НЕДЕЛЯ — 3–9 августа
A7: fishes43 | C7: 1900 | D7: MAX | E7: Сайт | F7: telega in | G7: t27 | H7: 46242 | I7: Вышло | J7: 769 | M7: =IF(N($J7)+N($K7)+N($L7)=0,"",N($J7)+N($K7)+N($L7)) -> 769 | O7: https://trigger-fish.ru/?utm_source=max&utm_medium=publik&utm_campaign=rybalkasakhalin&utm_content=t27&utm_term=0 | S7: https://max.ru/fishes43/AZ_f9UjBUjw | U7: 1062 | V7: =IF(N($U7)=0,"",$M7/$U7) -> 0.72410546 | W7: 22 | Y7: =IF(N($W7)=0,"",$M7/$W7) -> 34.954545 | Z7: 1 | AD7: 0 | AJ7: 3 дня
A8: Клёвое место | Рыбалка | B8: =IF($A8="","",IFERROR(HYPERLINK(VLOOKUP($A8,'Мои блогеры'!$A:$N,14,0),"🔗 открыть"),"")) -> 🔗 открыть | C8: 33000 | D8: MAX | E8: Сайт | F8: telega in | G8: t27 | H8: 46241 | I8: Вышло | J8: 10699 | L8: - | M8: =IF(N($J8)+N($K8)+N($L8)=0,"",N($J8)+N($K8)+N($L8)) -> 10699 | O8: https://trigger-fish.ru/?utm_source=max&utm_medium=publik&utm_campaign=klevoemesto&utm_content=t27&utm_term=0 | S8: https://max.ru/join/uCdz6lLBZaKQQ-TBrM1kCaXNxdhno0LlLSpv1_WO-yI | U8: 9852 | V8: =IF(N($U8)=0,"",$M8/$U8) -> 1.0859724 | W8: 262 | Y8: =IF(N($W8)=0,"",$M8/$W8) -> 40.835878 | Z8: 33 | AA8: 5 | AB8: 2950 | AD8: 2 | AE8: =AB8/AD8 -> 1475 | AF8: 1770 | AG8: =IF(N($AD8)=0,"",ROUND($M8/$AD8,0)) -> 5350 | AH8: =IF(N($AA8)=0,"",ROUND($M8/$AA8,0)) -> 2140 | AJ8: пост на месяц
A9: rybalka_severozapad | B9: =IF($A9="","",IFERROR(HYPERLINK(VLOOKUP($A9,'Мои блогеры'!$A:$N,14,0),"🔗 открыть"),"")) -> 🔗 открыть | C9: 5000 | D9: MAX | E9: Сайт | F9: telega in | G9: t27 | H9: 46241 | I9: Вышло | J9: 6933 | M9: =IF(N($J9)+N($K9)+N($L9)=0,"",N($J9)+N($K9)+N($L9)) -> 6933 | O9: https://trigger-fish.ru/?utm_source=max&utm_medium=publik&utm_campaign=rybalka_severozapad&utm_content=t27&utm_term=0 | S9: https://max.ru/rybalka_severozapad/AZ_anGIoWTQ | U9: 3067 | V9: =IF(N($U9)=0,"",$M9/$U9) -> 2.2605152 | W9: 70 | Y9: =IF(N($W9)=0,"",$M9/$W9) -> 99.042857 | Z9: 4 | AA9: 4 | AB9: 1180 | AD9: 1 | AE9: =AB9/AD9 -> 1180 | AF9: 1180 | AG9: =IF(N($AD9)=0,"",ROUND($M9/$AD9,0)) -> 6933 | AH9: =IF(N($AA9)=0,"",ROUND($M9/$AA9,0)) -> 1733 | AJ9: пост на месяц
A10: РЫБАЛКА В МОСКВЕ И ПОДМОСКОВЬЕ | B10: =IF($A10="","",IFERROR(HYPERLINK(VLOOKUP($A10,'Мои блогеры'!$A:$N,14,0),"🔗 открыть"),"")) -> 🔗 открыть | C10: =IFERROR(VLOOKUP($A10,'Мои блогеры'!$A:$N,5,0),"") -> 8699 | D10: Telegram | E10: Сайт | F10: telega in | G10: t27 | H10: 46243 | I10: Вышло | J10: =IFERROR(VLOOKUP($A10,'Мои блогеры'!$A:$N,8,0),"") -> 755 | M10: =IF(N($J10)+N($K10)+N($L10)=0,"",N($J10)+N($K10)+N($L10)) -> 755 | O10: https://trigger-fish.ru/?utm_source=max&utm_medium=publik&utm_campaign=rybalkavmoskve&utm_content=t27&utm_term=0 | S10: https://telegram.me/rubalkamoskva/42761 | U10: 1357 | V10: =IF(N($U10)=0,"",$M10/$U10) -> 0.55637436 | W10: 37 | Y10: =IF(N($W10)=0,"",$M10/$W10) -> 20.405405 | Z10: 10 | AA10: 4 | AB10: 2360 | AD10: 0 | AG10: =IF(N($AD10)=0,"",ROUND($M10/$AD10,0)) | AJ10: пост на месяц
A11: we_and_nature | B11: =IF($A11="","",IFERROR(HYPERLINK(VLOOKUP($A11,'Мои блогеры'!$A:$N,14,0),"🔗 открыть"),"")) -> 🔗 открыть | C11: =IFERROR(VLOOKUP($A11,'Мои блогеры'!$A:$N,5,0),"") -> 7000 | D11: MAX | E11: Сайт | F11: telega in | G11: t28 | H11: 46243 | I11: Вышло | J11: 3776 | M11: =IF(N($J11)+N($K11)+N($L11)=0,"",N($J11)+N($K11)+N($L11)) -> 3776 | O11: https://trigger-fish.ru/?utm_source=max&utm_medium=publik&utm_campaign=we_and_nature&utm_content=t28&utm_term=0 | S11: https://max.ru/we_and_nature/AZ_nQLlvTwc | U11: 3637 | V11: =IF(N($U11)=0,"",$M11/$U11) -> 1.0382183 | W11: 18 | Y11: =IF(N($W11)=0,"",$M11/$W11) -> 209.77778 | Z11: 1 | AD11: 0 | AG11: =IF(N($AD11)=0,"",ROUND($M11/$AD11,0)) | AJ11: пост на месяц
A12: Рыбалка | B12: =IF($A12="","",IFERROR(HYPERLINK(VLOOKUP($A12,'Мои блогеры'!$A:$N,14,0),"🔗 открыть"),"")) -> 🔗 открыть | C12: =IFERROR(VLOOKUP($A12,'Мои блогеры'!$A:$N,5,0),"") -> 25900 | D12: MAX | E12: Сайт | F12: telega in | G12: t28 | H12: 46242 | I12: Вышло | J12: 3216 | M12: =IF(N($J12)+N($K12)+N($L12)=0,"",N($J12)+N($K12)+N($L12)) -> 3216 | O12: https://trigger-fish.ru/?utm_source=max&utm_medium=publik&utm_campaign=rybalka&utm_content=t28&utm_term=0 | S12: https://max.ru/telefishing/AZ_gLNBzC3g | U12: 3380 | V12: =IF(N($U12)=0,"",$M12/$U12) -> 0.95147929 | W12: 91 | Y12: =IF(N($W12)=0,"",$M12/$W12) -> 35.340659 | Z12: 15 | AA12: 4 | AB12: 1180 | AD12: 1 | AE12: =AB12/AD12 -> 1180 | AF12: 1180 | AG12: =IF(N($AD12)=0,"",ROUND($M12/$AD12,0)) -> 3216 | AH12: =IF(N($AA12)=0,"",ROUND($M12/$AA12,0)) -> 804 | AJ12: на сутки
A13: Рыболовная сводка Спб | B13: =IF($A13="","",IFERROR(HYPERLINK(VLOOKUP($A13,'Мои блогеры'!$A:$N,14,0),"🔗 открыть"),"")) -> 🔗 открыть | C13: =IFERROR(VLOOKUP($A13,'Мои блогеры'!$A:$N,5,0),"") -> 35500 | D13: Telegram | E13: Сайт | F13: telega in | G13: t28 | H13: 46241 | I13: Вышло | J13: 6293 | M13: =IF(N($J13)+N($K13)+N($L13)=0,"",N($J13)+N($K13)+N($L13)) -> 6293 | O13: https://trigger-fish.ru/?utm_source=max&utm_medium=publik&utm_campaign=rybalovnayasvodkaspb&utm_content=t28&utm_term=0 | S13: https://max.ru/rybalka_severozapad/AZ_dYejXTGo | U13: 2650 | V13: =IF(N($U13)=0,"",$M13/$U13) -> 2.374717 | W13: 40 | Y13: =IF(N($W13)=0,"",$M13/$W13) -> 157.325 | Z13: 12 | AA13: 4 | AB13: 1180 | AD13: 0 | AG13: =IF(N($AD13)=0,"",ROUND($M13/$AD13,0)) | AJ13: пост на месяц
A14: rybalkasakhalin | C14: =IFERROR(VLOOKUP($A14,'Мои блогеры'!$A:$N,5,0),"") -> 12300 | D14: MAX | E14: Сайт | F14: telega in | G14: t28 | H14: 46241 | I14: Вышло | J14: =IFERROR(VLOOKUP($A14,'Мои блогеры'!$A:$N,8,0),"") -> 6933 | M14: =IF(N($J14)+N($K14)+N($L14)=0,"",N($J14)+N($K14)+N($L14)) -> 6933 | O14: https://trigger-fish.ru/?utm_source=max&utm_medium=publik&utm_campaign=rybalkasakhalin&utm_content=28 | S14: https://max.ru/rybalkasakhalin/AZ_mXo2jbBY | U14: 5090 | V14: =IF(N($U14)=0,"",$M14/$U14) -> 1.3620825 | W14: 39 | Y14: =IF(N($W14)=0,"",$M14/$W14) -> 177.76923 | Z14: 6 | AD14: 0 | AJ14: пост на месяц
A15: Итого:3-9 августа | I15: =COUNTIF(I7:I14,"Вышло")&" / "&COUNTA(A7:A14) -> 8 / 8 | J15: =SUM(J7:J14) -> 39374 | L15: =SUM(L8:L14) -> 0 | M15: =SUM(M7:M14) -> 39374 | N15: =SUM(N7:N14) -> 0 | O15: =SUM(O7:O14) -> 0 | P15: =SUM(P7:P14) -> 0 | Q15: =SUM(Q7:Q14) -> 0 | R15: =SUM(R7:R14) -> 0 | S15: =SUM(S7:S14) -> 0 | U15: =SUM(U7:U14) -> 30095 | V15: =SUM(V7:V14) -> 10.353464 | W15: =SUM(W7:W14) -> 579 | X15: =SUM(X7:X14) -> 0 | Y15: =SUM(Y7:Y14) -> 775.45135 | Z15: =SUM(Z7:Z14) -> 82 | AA15: =SUM(AA7:AA14) -> 21 | AB15: =SUM(AB7:AB14) -> 8850 | AD15: =SUM(AD7:AD14) -> 4 | AE15: =SUM(AE7:AE14) -> 3835 | AF15: =SUM(AF7:AF14) -> 4130 | AG15: =SUM(AG7:AG14) -> 15499 | AH15: =SUM(AH7:AH14) -> 4677
A16: НЕДЕЛЯ —10–17августа
A17: viktorlife24 | C17: =IFERROR(VLOOKUP($A17,'Мои блогеры'!$A:$N,5,0),"") -> 33000 | D17: TikTok | E17: WB | F17: 6 | G17: v1 | H17: 46248 | I17: Вышло | J17: =IFERROR(VLOOKUP($A17,'Мои блогеры'!$A:$N,8,0),"") -> 50000 | K17: 1800 | L17: 780 | M17: =IF(N($J17)+N($K17)+N($L17)=0,"",N($J17)+N($K17)+N($L17)) -> 52580 | N17: 2W5zFJrZboX | O17: https://wildberries.ru/catalog/0/search.aspx?search=WW888364 | P17: https://aminotriggerfish.mobz.market/7icq | R17: WW888364 | S17: https://vt.tiktok.com/ZSVewxP5s/ | T17: Да | U17: 243800 | V17: =IF(N($U17)=0,"",$M17/$U17) -> 0.21566858 | W17: 1063 | X17: 14 | Y17: =IF(N($W17)=0,"",$M17/$W17) -> 49.463782 | Z17: 126 | AA17: 17 | AB17: =743*AA17 -> 12631 | AD17: 17 | AE17: 743 | AF17: =AB17 -> 12631 | AG17: =IF(N($AD17)=0,"",ROUND($M17/$AD17,0)) -> 3093 | AH17: =IF(N($AA17)=0,"",ROUND($M17/$AA17,0)) -> 3093
A18: viktorlife24youtube | C18: =IFERROR(VLOOKUP($A18,'Мои блогеры'!$A:$N,5,0),"") -> 6000 | D18: YouTube | E18: WB | F18: 6 | G18: v1 | H18: 46248 | I18: Вышло | J18: =IFERROR(VLOOKUP($A18,'Мои блогеры'!$A:$N,8,0),"") -> 15000 | K18: 930 | L18: 0 | M18: =IF(N($J18)+N($K18)+N($L18)=0,"",N($J18)+N($K18)+N($L18)) -> 15930 | N18: 2W5zFJPtADF | O18: https://wildberries.ru/catalog/0/search.aspx?search=WW888378 | P18: https://aminotriggerfish.mobz.market/hs9mwe | R18: WW888378 | S18: https://youtube.com/shorts/rKxxYD_SDCc?si=B1QcWbyyjv0rHg-u | T18: Да | U18: 80000 | V18: =IF(N($U18)=0,"",$M18/$U18) -> 0.199125 | W18: 105 | X18: - | Y18: =IF(N($W18)=0,"",$M18/$W18) -> 151.71429 | Z18: 18 | AA18: 3 | AB18: =743*AA18 -> 2229 | AD18: 3 | AE18: 743 | AF18: =AB18 -> 2229 | AG18: =IF(N($AD18)=0,"",ROUND($M18/$AD18,0)) -> 5310 | AH18: =IF(N($AA18)=0,"",ROUND($M18/$AA18,0)) -> 5310
A19: fishercl | B19: =IF($A19="","",IFERROR(HYPERLINK(VLOOKUP($A19,'Мои блогеры'!$A:$N,14,0),"🔗 открыть"),"")) -> 🔗 открыть | C19: =IFERROR(VLOOKUP($A19,'Мои блогеры'!$A:$N,5,0),"") -> 22400 | D19: Telegram | E19: Сайт | F19: telega in | G19: t27 | H19: 46249 | I19: Вышло | J19: =IFERROR(VLOOKUP($A19,'Мои блогеры'!$A:$N,8,0),"") -> 1818 | M19: =IF(N($J19)+N($K19)+N($L19)=0,"",N($J19)+N($K19)+N($L19)) -> 1818 | O19: https://trigger-fish.ru/?utm_source=tg&utm_medium=publik&utm_campaign=fishercl&utm_content=t27 | S19: https://telegram.me/fishercl/5219 | U19: 3840 | V19: =IF(N($U19)=0,"",$M19/$U19) -> 0.4734375 | W19: 12 | Y19: =IF(N($W19)=0,"",$M19/$W19) -> 151.5 | Z19: 1 | AF19: =IF(OR(N($AD19)=0,$AE19=""),"",ROUND($AD19*$AE19,0)) | AG19: =IF(N($AD19)=0,"",ROUND($M19/$AD19,0)) | AH19: =IF(N($AA19)=0,"",ROUND($M19/$AA19,0)) | AJ19: 2 суток
A20: alexeyvfishing | B20: =IF($A20="","",IFERROR(HYPERLINK(VLOOKUP($A20,'Мои блогеры'!$A:$N,14,0),"🔗 открыть"),"")) -> 🔗 открыть | C20: =IFERROR(VLOOKUP($A20,'Мои блогеры'!$A:$N,5,0),"") -> 4000 | D20: MAX | E20: Сайт | F20: telega in | G20: t27 | H20: 46249 | I20: Вышло | J20: 349 | M20: =IF(N($J20)+N($K20)+N($L20)=0,"",N($J20)+N($K20)+N($L20)) -> 349 | O20: https://trigger-fish.ru/?utm_source=max&utm_medium=publik&utm_campaign=alexeyvfishing&utm_content=t27 | S20: https://max.ru/alexeyvfishing/AaAEOW_-O0w | U20: 652 | V20: =IF(N($U20)=0,"",$M20/$U20) -> 0.53527607 | W20: 16 | Y20: =IF(N($W20)=0,"",$M20/$W20) -> 21.8125 | Z20: 15 | AF20: =IF(OR(N($AD20)=0,$AE20=""),"",ROUND($AD20*$AE20,0)) | AG20: =IF(N($AD20)=0,"",ROUND($M20/$AD20,0)) | AH20: =IF(N($AA20)=0,"",ROUND($M20/$AA20,0))
A21: Рыбалка СПб и Карелия | B21: =IF($A21="","",IFERROR(HYPERLINK(VLOOKUP($A21,'Мои блогеры'!$A:$N,14,0),"🔗 открыть"),"")) -> 🔗 открыть | C21: =IFERROR(VLOOKUP($A21,'Мои блогеры'!$A:$N,5,0),"") -> 3300 | D21: MAX | E21: Сайт | F21: telega in | G21: t27 | H21: 46249 | I21: Вышло | J21: =IFERROR(VLOOKUP($A21,'Мои блогеры'!$A:$N,8,0),"") -> 560 | M21: =IF(N($J21)+N($K21)+N($L21)=0,"",N($J21)+N($K21)+N($L21)) -> 560 | O21: https://trigger-fish.ru/?utm_source=max&utm_medium=publik&utm_campaign=spbkorel&utm_content=t27 | S21: https://max.ru/fishingspb1/AaAEcE1jd0w | U21: 930 | V21: =IF(N($U21)=0,"",$M21/$U21) -> 0.60215054 | W21: 18 | Y21: =IF(N($W21)=0,"",$M21/$W21) -> 31.111111 | Z21: 15 | AA21: 2 | AB21: 1180 | AG21: =IF(N($AD21)=0,"",ROUND($M21/$AD21,0))
A22: rubalkarussia | B22: =IF($A22="","",IFERROR(HYPERLINK(VLOOKUP($A22,'Мои блогеры'!$A:$N,14,0),"🔗 открыть"),"")) -> 🔗 открыть | C22: =IFERROR(VLOOKUP($A22,'Мои блогеры'!$A:$N,5,0),"") -> 7800 | D22: MAX | E22: Сайт | F22: telega in | G22: t27 | H22: 46249 | I22: Вышло | J22: 2097 | M22: =IF(N($J22)+N($K22)+N($L22)=0,"",N($J22)+N($K22)+N($L22)) -> 2097 | O22: https://trigger-fish.ru/?utm_source=max&utm_medium=publik&utm_campaign=max.ru%2Frubalkarussia&utm_content=t27 | S22: https://max.ru/rubalkarussia/AaAGSbIzf8g | U22: 2329 | V22: =IF(N($U22)=0,"",$M22/$U22) -> 0.90038643 | W22: 41 | Y22: =IF(N($W22)=0,"",$M22/$W22) -> 51.146341 | Z22: 2 | AG22: =IF(N($AD22)=0,"",ROUND($M22/$AD22,0))
A23: fish_journal дневник | B23: =IF($A23="","",IFERROR(HYPERLINK(VLOOKUP($A23,'Мои блогеры'!$A:$N,14,0),"🔗 открыть"),"")) | C23: 5933 | D23: MAX | E23: Сайт | F23: telega in | G23: t27 | H23: 46249 | I23: Вышло | J23: 1258 | M23: =IF(N($J23)+N($K23)+N($L23)=0,"",N($J23)+N($K23)+N($L23)) -> 1258 | O23: https://trigger-fish.ru/?utm_source=max&utm_medium=publik&utm_campaign=fish_journal&utm_content=t27 | S23: https://max.ru/fish_journal/AaAEqvUQEUw | U23: 1493 | V23: =IF(N($U23)=0,"",$M23/$U23) -> 0.84259879 | W23: 74 | Y23: =IF(N($W23)=0,"",$M23/$W23) -> 17 | Z23: 16 | AA23: 4 | AB23: 2360 | AG23: =IF(N($AD23)=0,"",ROUND($M23/$AD23,0))
A24: Рыбалка в Нижнем Новгороде | B24: =IF($A24="","",IFERROR(HYPERLINK(VLOOKUP($A24,'Мои блогеры'!$A:$N,14,0),"🔗 открыть"),"")) -> 🔗 открыть | C24: =IFERROR(VLOOKUP($A24,'Мои блогеры'!$A:$N,5,0),"") -> 453 | D24: MAX | E24: Сайт | F24: telega in | G24: t27 | H24: 46249 | I24: Вышло | J24: =IFERROR(VLOOKUP($A24,'Мои блогеры'!$A:$N,8,0),"") -> 350 | M24: =IF(N($J24)+N($K24)+N($L24)=0,"",N($J24)+N($K24)+N($L24)) -> 350 | O24: https://trigger-fish.ru/?utm_source=max&utm_medium=publik&utm_campaign=channel_rybalka_52&utm_content=t27 | S24: https://max.ru/channel_Rybalka_52/AaAGlQguSww | U24: 505 | V24: =IF(N($U24)=0,"",$M24/$U24) -> 0.69306931 | W24: 35 | Y24: =IF(N($W24)=0,"",$M24/$W24) -> 10 | Z24: 1 | AG24: =IF(N($AD24)=0,"",ROUND($M24/$AD24,0))
A25: Рыбалка по-русски | B25: =IF($A25="","",IFERROR(HYPERLINK(VLOOKUP($A25,'Мои блогеры'!$A:$N,14,0),"🔗 открыть"),"")) -> 🔗 открыть | C25: =IFERROR(VLOOKUP($A25,'Мои блогеры'!$A:$N,5,0),"") -> 1200 | D25: MAX | E25: Сайт | F25: telega in | G25: t27 | H25: 46249 | I25: Вышло | J25: =IFERROR(VLOOKUP($A25,'Мои блогеры'!$A:$N,8,0),"") -> 532 | M25: =IF(N($J25)+N($K25)+N($L25)=0,"",N($J25)+N($K25)+N($L25)) -> 532 | O25: https://trigger-fish.ru/?utm_source=max&utm_medium=publik&utm_campaign=russian_fishing_pro&utm_content=t27 | S25: https://max.ru/russian_fishing_pro/AaAG5yAKQQw | U25: 892 | V25: =IF(N($U25)=0,"",$M25/$U25) -> 0.59641256 | W25: 10 | Y25: =IF(N($W25)=0,"",$M25/$W25) -> 53.2 | Z25: 1 | AG25: =IF(N($AD25)=0,"",ROUND($M25/$AD25,0)) | AH25: =IF(N($AA25)=0,"",ROUND($M25/$AA25,0))
A26: Рыбалка. Рыба. Рыбаки🎣 | B26: =IF($A26="","",IFERROR(HYPERLINK(VLOOKUP($A26,'Мои блогеры'!$A:$N,14,0),"🔗 открыть"),"")) -> 🔗 открыть | C26: =IFERROR(VLOOKUP($A26,'Мои блогеры'!$A:$N,5,0),"") -> 2800 | D26: MAX | E26: Сайт | F26: telega in | G26: t27 | H26: 46249 | I26: Вышло | J26: =IFERROR(VLOOKUP($A26,'Мои блогеры'!$A:$N,8,0),"") -> 979 | M26: =IF(N($J26)+N($K26)+N($L26)=0,"",N($J26)+N($K26)+N($L26)) -> 979 | O26: https://trigger-fish.ru/?utm_source=max&utm_medium=publik&utm_campaign=rybalka555&utm_content=t27 | S26: https://max.ru/rybalka555/AaADy5FHb0w | U26: 1429 | V26: =IF(N($U26)=0,"",$M26/$U26) -> 0.68509447 | W26: 36 | Y26: =IF(N($W26)=0,"",$M26/$W26) -> 27.194444 | Z26: 1 | AD26: =IF(OR(N($AA26)=0,$AC26=""),"",ROUND($AA26*$AC26,0)) | AF26: =IF(OR(N($AD26)=0,$AE26=""),"",ROUND($AD26*$AE26,0)) | AG26: =IF(N($AD26)=0,"",ROUND($M26/$AD26,0)) | AH26: =IF(N($AA26)=0,"",ROUND($M26/$AA26,0))
A27: Рыбалка на фидер в Санкт-Петербурге | C27: =IFERROR(VLOOKUP($A27,'Мои блогеры'!$A:$N,5,0),"") -> 2700 | D27: Telegram | E27: Сайт | F27: telega in | G27: t27 | H27: 46249 | I27: Вышло | J27: 293 | M27: =IF(N($J27)+N($K27)+N($L27)=0,"",N($J27)+N($K27)+N($L27)) -> 293 | O27: https://trigger-fish.ru/?utm_source=max&utm_medium=publik&utm_campaign=feeder_spb&utm_content=t27 | S27: https://telegram.me/feeder_spb/10105 | U27: 1329 | V27: =IF(N($U27)=0,"",$M27/$U27) -> 0.22046652 | W27: 11 | Y27: =IF(N($W27)=0,"",$M27/$W27) -> 26.636364 | Z27: 1 | AF27: =IF(OR(N($AD27)=0,$AE27=""),"",ROUND($AD27*$AE27,0)) | AG27: =IF(N($AD27)=0,"",ROUND($M27/$AD27,0)) | AH27: =IF(N($AA27)=0,"",ROUND($M27/$AA27,0))
A28: РЫБАКИ КУБАНЬ АДЫГЕЯ | ОТЧЕТЫ | C28: =IFERROR(VLOOKUP($A28,'Мои блогеры'!$A:$N,5,0),"") -> 3900 | D28: MAX | E28: Сайт | F28: telega in | G28: t27 | H28: 46249 | I28: Вышло | J28: =IFERROR(VLOOKUP($A28,'Мои блогеры'!$A:$N,8,0),"") -> 700 | M28: =IF(N($J28)+N($K28)+N($L28)=0,"",N($J28)+N($K28)+N($L28)) -> 700 | O28: https://trigger-fish.ru/?utm_source=max&utm_medium=publik&utm_campaign=fishing_kuban_adygea&utm_content=t27 | S28: https://max.ru/Fishing_Kuban_Adygea/AaAFS5vOGOw | U28: 1304 | V28: =IF(N($U28)=0,"",$M28/$U28) -> 0.53680982 | W28: 39 | Y28: =IF(N($W28)=0,"",$M28/$W28) -> 17.948718 | Z28: 1 | AF28: =IF(OR(N($AD28)=0,$AE28=""),"",ROUND($AD28*$AE28,0)) | AG28: =IF(N($AD28)=0,"",ROUND($M28/$AD28,0)) | AH28: =IF(N($AA28)=0,"",ROUND($M28/$AA28,0))
A29: Рыбалка на Волге | Самарская рыбалка | C29: =IFERROR(VLOOKUP($A29,'Мои блогеры'!$A:$N,5,0),"") -> 7200 | D29: Telegram | E29: Сайт | F29: telega in | G29: t27 | H29: 46249 | I29: Вышло | J29: =IFERROR(VLOOKUP($A29,'Мои блогеры'!$A:$N,8,0),"") -> 700 | M29: =IF(N($J29)+N($K29)+N($L29)=0,"",N($J29)+N($K29)+N($L29)) -> 700 | O29: https://trigger-fish.ru/?utm_source=telegram&utm_medium=publik&utm_campaign=samarafish&utm_content=t27 | S29: https://telegram.me/samarafish/19820 | U29: 1839 | V29: =IF(N($U29)=0,"",$M29/$U29) -> 0.38064165 | W29: 6 | Y29: =IF(N($W29)=0,"",$M29/$W29) -> 116.66667 | Z29: 3 | AF29: =IF(OR(N($AD29)=0,$AE29=""),"",ROUND($AD29*$AE29,0)) | AG29: =IF(N($AD29)=0,"",ROUND($M29/$AD29,0)) | AH29: =IF(N($AA29)=0,"",ROUND($M29/$AA29,0))
A30: РЫБАЛКА РОСТОВ И ОБЛАСТЬ🐟 | C30: =IFERROR(VLOOKUP($A30,'Мои блогеры'!$A:$N,5,0),"") -> 1600 | D30: MAX | E30: Сайт | F30: telega in | G30: t27 | H30: 46249 | I30: Вышло | J30: 699 | M30: =IF(N($J30)+N($K30)+N($L30)=0,"",N($J30)+N($K30)+N($L30)) -> 699 | O30: https://trigger-fish.ru/?utm_source=max&utm_medium=publik&utm_campaign=channel_rostov_fishing&utm_content=t27 | S30: https://max.ru/channel_Rostov_Fishing/AaAEOXtMP0w | U30: 979 | V30: =IF(N($U30)=0,"",$M30/$U30) -> 0.71399387 | W30: 71 | Y30: =IF(N($W30)=0,"",$M30/$W30) -> 9.8450704 | Z30: 2 | AF30: =IF(OR(N($AD30)=0,$AE30=""),"",ROUND($AD30*$AE30,0)) | AG30: =IF(N($AD30)=0,"",ROUND($M30/$AD30,0)) | AH30: =IF(N($AA30)=0,"",ROUND($M30/$AA30,0))
A31: Рыбалка | C31: =IFERROR(VLOOKUP($A31,'Мои блогеры'!$A:$N,5,0),"") -> 25900 | D31: MAX | E31: Сайт | F31: telega in | G31: t27 | H31: 46250 | I31: Вышло | J31: 3496 | M31: =IF(N($J31)+N($K31)+N($L31)=0,"",N($J31)+N($K31)+N($L31)) -> 3496 | O31: https://trigger-fish.ru/?utm_source=max&utm_medium=publik&utm_campaign=life_fishing&utm_content=t27 | S31: https://max.ru/life_fishing/AaAJXv4LLk0 | U31: 4593 | V31: =IF(N($U31)=0,"",$M31/$U31) -> 0.76115828 | W31: 72 | Y31: =IF(N($W31)=0,"",$M31/$W31) -> 48.555556 | Z31: 2 | AA31: 2 | AB31: 1180 | AG31: =IF(N($AD31)=0,"",ROUND($M31/$AD31,0)) | AH31: =IF(N($AA31)=0,"",ROUND($M31/$AA31,0)) -> 1748
A32: Итого 10-16 августа | I32: =SUM(I17:I31) -> 0 | J32: =SUM(J17:J31) -> 78831 | K32: =SUM(K17:K31) -> 2730 | L32: =SUM(L17:L31) -> 780 | M32: =SUM(M17:M31) -> 82341 | N32: =SUM(N17:N31) -> 0 | O32: =SUM(O17:O31) -> 0 | P32: =SUM(P17:P31) -> 0 | ... S32: =SUM(S17:S31) -> 0 | U32: =SUM(U17:U31) -> 345914 | V32: =SUM(V17:V31) -> 8.3562894 | W32: =SUM(W17:W31) -> 1609 | X32: =SUM(X17:X31) -> 14 | Y32: =SUM(Y17:Y31) -> 783.79484 | Z32: =SUM(Z17:Z31) -> 205 | AA32: =SUM(AA17:AA31) -> 28 | AB32: =SUM(AB17:AB31) -> 19580 | ... AH32: =SUM(AH17:AH31) -> 10151
A33: НЕДЕЛЯ — 17–23 августа
A34: https://vk.ru/fishinglifetv | B34: =IF($A34="","",IFERROR(HYPERLINK(VLOOKUP($A34,'Мои блогеры'!$A:$N,14,0),"🔗 открыть"),"")) -> 🔗 открыть | C34: =IFERROR(VLOOKUP($A34,'Мои блогеры'!$A:$N,5,0),"") -> 7800 | D34: =IFERROR(VLOOKUP($A34,'Мои блогеры'!$A:$N,2,0),"") -> VK | E34: Ozon | G34: свой сценарий | H34: 46256 | I34: Вышло | J34: =IFERROR(VLOOKUP($A34,'Мои блогеры'!$A:$N,8,0),"") -> 40000 | K34: 5000 | M34: =IF(N($J34)+N($K34)+N($L34)=0,"",N($J34)+N($K34)+N($L34)) -> 45000 | O34: https://ozon.onelink.me/SNMZ?af_dp=https://ozon.ru/product/aminotrigger-fish-aromatizator-dlya-rybalki-250-ml-5340361400/&af_web_dp=https://ozon.ru/product/aminotrigger-fish-aromatizator-dlya-rybalki-250-ml-5340361400/&is_retargeting=true&c=vendor_org_4202727_t28&pid=vk|video&af_keywords=fishinglifetv&hs=1&utm_source=vk&utm_medium=video&utm_campaign=vendor_org_4202727_t28&utm_term=fishinglifetv | P34: https://aminotriggerfish.mobz.market/b0g | S34: https://vk.ru/wall-226894765_643 | U34: 20300 | V34: =IF(N($U34)=0,"",$M34/$U34) -> 2.2167488 | W34: 116 | X34: - | Y34: =IF(N($W34)=0,"",$M34/$W34) -> 387.93103 | Z34: 18 | AD34: =IF(OR(N($AA34)=0,$AC34=""),"",ROUND($AA34*$AC34,0)) | AF34: =IF(OR(N($AD34)=0,$AE34=""),"",ROUND($AD34*$AE34,0)) | AG34: =IF(N($AD34)=0,"",ROUND($M34/$AD34,0)) | AH34: =IF(N($AA34)=0,"",ROUND($M34/$AA34,0)) | AJ34: тут будут еще доп посты
A35: pugleonid | B35: =IF($A35="","",IFERROR(HYPERLINK(VLOOKUP($A35,'Мои блогеры'!$A:$N,14,0),"🔗 открыть"),"")) -> 🔗 открыть | C35: =IFERROR(VLOOKUP($A35,'Мои блогеры'!$A:$N,5,0),"") -> 61000 | D35: =IFERROR(VLOOKUP($A35,'Мои блогеры'!$A:$N,2,0),"") -> VK | E35: Ozon | F35: 13 | G35: v1 | H35: 46253 | I35: Вышло | J35: =IFERROR(VLOOKUP($A35,'Мои блогеры'!$A:$N,8,0),"") -> 65000 | K35: =65000*0.09 -> 5850 | L35: 500 | M35: =IF(N($J35)+N($K35)+N($L35)=0,"",N($J35)+N($K35)+N($L35)) -> 71350 | O35: https://ozon.ru/product/aminotrigger-fish-aromatizator-dlya-rybalki-250-ml-5340361400/?hs=1&utm_campaign=vendor_org_4202727_pugleonid&utm_medium=video&utm_source=vk | P35: https://aminotriggerfish.mobz.market/s6i | S35: https://vk.ru/clip-221128641_456239567?c=1 | T35: Да | U35: 3900 | V35: =IF(N($U35)=0,"",$M35/$U35) -> 18.294872 | W35: 39 | X35: - | Y35: =IF(N($W35)=0,"",$M35/$W35) -> 1829.4872 | Z35: 24 | AD35: =IF(OR(N($AA35)=0,$AC35=""),"",ROUND($AA35*$AC35,0)) | AF35: =IF(OR(N($AD35)=0,$AE35=""),"",ROUND($AD35*$AE35,0)) | AG35: =IF(N($AD35)=0,"",ROUND($M35/$AD35,0)) | AH35: =IF(N($AA35)=0,"",ROUND($M35/$AA35,0)) | AJ35: дубль в други соц сети будет
A36: novo_fish | B36: =IF($A36="","",IFERROR(HYPERLINK(VLOOKUP($A36,'Мои блогеры'!$A:$N,14,0),"🔗 открыть"),"")) -> 🔗 открыть | C36: =IFERROR(VLOOKUP($A36,'Мои блогеры'!$A:$N,5,0),"") -> 7930 | D36: TikTok | E36: WB | G36: v1 | H36: 46257 | I36: Вышло | J36: =IFERROR(VLOOKUP($A36,'Мои блогеры'!$A:$N,8,0),"") -> 5000 | K36: 400 | L36: 822 | M36: =IF(N($J36)+N($K36)+N($L36)=0,"",N($J36)+N($K36)+N($L36)) -> 6222 | O36: https://wildberries.ru/catalog/0/search.aspx?search=WW947786 | R36: WW947786 | S36: https://www.tiktok.com/@novo_fish/video/7677190984953908513 | T36: Да | U36: 4489 | V36: =IF(N($U36)=0,"",$M36/$U36) -> 1.3860548 | W36: 17 | X36: - | Y36: =IF(N($W36)=0,"",$M36/$W36) -> 366 | Z36: 4 | AA36: 2 | AB36: =743*AA36 -> 1486 | AD36: 1 | AE36: =AB36/AD36 -> 1486 | AF36: =IF(OR(N($AD36)=0,$AE36=""),"",ROUND($AD36*$AE36,0)) -> 1486 | AG36: =IF(N($AD36)=0,"",ROUND($M36/$AD36,0)) -> 6222 | AH36: =IF(N($AA36)=0,"",ROUND($M36/$AA36,0)) -> 3111 | AJ36: только вышел
A37: Доступная рыбалка | B37: =IF($A37="","",IFERROR(HYPERLINK(VLOOKUP($A37,'Мои блогеры'!$A:$N,14,0),"🔗 открыть"),"")) -> 🔗 открыть | C37: =IFERROR(VLOOKUP($A37,'Мои блогеры'!$A:$N,5,0),"") -> 27100 | D37: =IFERROR(VLOOKUP($A37,'Мои блогеры'!$A:$N,2,0),"") -> VK | E37: Ozon | G37: t27 | H37: 46256 | I37: Вышло | J37: =IFERROR(VLOOKUP($A37,'Мои блогеры'!$A:$N,8,0),"") -> 13000 | K37: 780 | M37: =IF(N($J37)+N($K37)+N($L37)=0,"",N($J37)+N($K37)+N($L37)) -> 13780 | O37: https://ozon.onelink.me/SNMZ?af_dp=https://ozon.ru/product/aminotrigger-fish-aromatizator-dlya-rybalki-250-ml-5340361400/&af_web_dp=https://ozon.ru/product/aminotrigger-fish-aromatizator-dlya-rybalki-250-ml-5340361400/&is_retargeting=true&c=vendor_org_4202727_доступная рыбалка &pid=vk|blog&af_adset=т28 &hs=1&utm_source=vk&utm_medium=blog&utm_campaign=vendor_org_4202727_доступная+рыбалка &utm_content=т28 | S37: https://vk.ru/wall-136853349_64568 | U37: 24930 | V37: =IF(N($U37)=0,"",$M37/$U37) -> 0.55274769 | W37: 42 | Y37: =IF(N($W37)=0,"",$M37/$W37) -> 328.09524 | Z37: 8 | AD37: =IF(OR(N($AA37)=0,$AC37=""),"",ROUND($AA37*$AC37,0)) | AF37: =IF(OR(N($AD37)=0,$AE37=""),"",ROUND($AD37*$AE37,0)) | AG37: =IF(N($AD37)=0,"",ROUND($M37/$AD37,0)) | AH37: =IF(N($AA37)=0,"",ROUND($M37/$AA37,0)) | AJ37: сутки
A38: Рыбалка в кайф | C38: =IFERROR(VLOOKUP($A38,'Мои блогеры'!$A:$N,5,0),"") -> 761 | D38: MAX | E38: Сайт | F38: telega in | G38: t27 | H38: 46255 | I38: Вышло | J38: =IFERROR(VLOOKUP($A38,'Мои блогеры'!$A:$N,8,0),"") -> 348 | M38: =IF(N($J38)+N($K38)+N($L38)=0,"",N($J38)+N($K38)+N($L38)) -> 348 | O38: https://trigger-fish.ru/?utm_source=max&utm_medium=publik&utm_campaign=vkaifl_riabalka&utm_content=t27 | S38: https://max.ru/channel_riabalka/AaAiQ4ZBKcY | U38: 338 | V38: =IF(N($U38)=0,"",$M38/$U38) -> 1.0295858 | W38: 22 | Y38: =IF(N($W38)=0,"",$M38/$W38) -> 15.818182 | Z38: 3 | AJ38: сутки
A39: Рыбалка | Клёвое место | C39: =IFERROR(VLOOKUP($A39,'Мои блогеры'!$A:$N,5,0),"") -> 4200 | D39: MAX | E39: Сайт | F39: telega in | G39: t27 | H39: 46255 | I39: Вышло | J39: =IFERROR(VLOOKUP($A39,'Мои блогеры'!$A:$N,8,0),"") -> 980 | M39: =IF(N($J39)+N($K39)+N($L39)=0,"",N($J39)+N($K39)+N($L39)) -> 980 | O39: https://trigger-fish.ru/?utm_source=max&utm_medium=publik&utm_campaign=rybalka_7&utm_content=t27 | S39: https://max.ru/rybalka_7/AaAiQ3aoC8Y | U39: 1114 | V39: =IF(N($U39)=0,"",$M39/$U39) -> 0.87971275 | W39: 35 | Y39: =IF(N($W39)=0,"",$M39/$W39) -> 28 | Z39: 2 | AJ39: сутки
A40: блог рыбака | C40: =IFERROR(VLOOKUP($A40,'Мои блогеры'!$A:$N,5,0),"") -> 1600 | D40: MAX | E40: Сайт | F40: telega in | G40: t27 | H40: 46255 | I40: Вышло | J40: =IFERROR(VLOOKUP($A40,'Мои блогеры'!$A:$N,8,0),"") -> 392 | M40: =IF(N($J40)+N($K40)+N($L40)=0,"",N($J40)+N($K40)+N($L40)) -> 392 | O40: https://trigger-fish.ru/?utm_source=max&utm_medium=publik&utm_campaign=blogrybaka&utm_content=t27 | S40: https://max.ru/join/-B1pH9O5LwDun19v5QK_CES0a8YCZ940MUNS4gEcKOo | U40: 481 | V40: =IF(N($U40)=0,"",$M40/$U40) -> 0.81496881 | W40: 12 | Y40: =IF(N($W40)=0,"",$M40/$W40) -> 32.666667 | Z40: 1 | AJ40: сутки
A41: В САДКЕ - Рыбалка Хабаровский край и ДВ | C41: =IFERROR(VLOOKUP($A41,'Мои блогеры'!$A:$N,5,0),"") -> 1200 | D41: MAX | E41: Сайт | F41: telega in | G41: t27 | H41: 46255 | I41: Вышло | J41: =IFERROR(VLOOKUP($A41,'Мои блогеры'!$A:$N,8,0),"") -> 1258 | M41: =IF(N($J41)+N($K41)+N($L41)=0,"",N($J41)+N($K41)+N($L41)) -> 1258 | O41: https://trigger-fish.ru/?utm_source=max&utm_medium=publik&utm_campaign=channel_vsadke&utm_content=t27 | S41: https://max.ru/channel_VSADKE/AaAjWQZCNeY | U41: 769 | V41: =IF(N($U41)=0,"",$M41/$U41) -> 1.6358908 | W41: 15 | Y41: =IF(N($W41)=0,"",$M41/$W41) -> 83.866667 | Z41: 1 | AJ41: сутки
...

Sheet Сентябрь
A1: не
A2: Выбери блогера в колонке A — ссылка, подписчики, площадка, промокод, стоимость подтянутся. «🔗 открыть» ведёт на канал.
A3: Выкупы = Заказы × %выкупа. Выручка = Средний чек × Выкупы. CAC/CPO по факту.
A5: Блогер | B5: Ссылка на канал | C5: Подписчики | D5: Площадка | E5: Канал продаж | F5: № договора | G5: Сценарий рекламы | H5: Дата выхода | I5: Статус | J5: Стоимость размещения | K5: Налог | L5: Себестоимость продукции | M5: Итого к оплате | N5: Код маркировки (ERID) | O5: Ссылка с UTM | P5: Ссылка Мобзио | Q5: Промокод | R5: Подменный артикул | S5: Ссылка на размещение | T5: Право использования | U5: Охват факт | V5: CPV, ₽ | W5: Клики WB/ сайт | X5: Клики мобзио | Y5: Цена за клик, ₽ | Z5: Корзины | AA5: Заказы | AB5: Сумма заказов, ₽ | AC5: % выкупа | AD5: Выкупы | AE5: Средний чек, ₽ | AF5: Выручка от выкупов, ₽ | AG5: Стоимость выкупа, ₽ | AH5: CPO, ₽ | AI5: Продукт | AJ5: РЕГ | AK5: CPA | AL5: Комментарий
A6: НЕДЕЛЯ —1–7 сентября
A7: https://www.tiktok.com/@batya_ilin | B7: =IF($A7="","",IFERROR(HYPERLINK(VLOOKUP($A7,'Мои блогеры'!$A:$N,14,0),"🔗 открыть"),"")) -> 🔗 открыть | C7: =IFERROR(VLOOKUP($A7,'Мои блогеры'!$A:$N,5,0),"") -> 84300 | D7: =IFERROR(VLOOKUP($A7,'Мои блогеры'!$A:$N,2,0),"") -> TikTok | E7: Ozon | F7: 22 | G7: v1 | H7: 46266 | I7: Вышло | J7: =IFERROR(VLOOKUP($A7,'Мои блогеры'!$A:$N,8,0),"") -> 30000 | K7: 1500 | M7: =IF(N($J7)+N($K7)+N($L7)=0,"",N($J7)+N($K7)+N($L7)) -> 31500 | N7: 2W5zFJ8vuds | O7: - | Q7: BATYA10 | R7: - | S7: https://vt.tiktok.com/ZSVKS2TKF/ | T7: Да | U7: 585100 | V7: =IF(N($U7)=0,"",$M7/$U7) -> 0.053836951 | W7: - | Y7: =IF(N($W7)=0,"",$M7/$W7) | AA7: 2 | AB7: 2160 | AD7: 2 | AE7: =AB7/AD7 -> 1080 | AF7: =IF(OR(N($AD7)=0,$AE7=""),"",ROUND($AD7*$AE7,0)) -> 2160 | AG7: =IF(N($AD7)=0,"",ROUND($M7/$AD7,0)) -> 15750 | AH7: =IF(N($AA7)=0,"",ROUND($M7/$AA7,0)) -> 15750 | AI7: Aminotrigger-Fish
A8: https://vk.ru/batya_ilin | B8: =IF($A8="","",IFERROR(HYPERLINK(VLOOKUP($A8,'Мои блогеры'!$A:$N,14,0),"🔗 открыть"),"")) -> 🔗 открыть | C8: =IFERROR(VLOOKUP($A8,'Мои блогеры'!$A:$N,5,0),"") -> 60500 | D8: =IFERROR(VLOOKUP($A8,'Мои блогеры'!$A:$N,2,0),"") -> VK | E8: Ozon | F8: 22 | G8: v1 | H8: 46270 | I8: Вышло | J8: =IFERROR(VLOOKUP($A8,'Мои блогеры'!$A:$N,8,0),"") -> 20000 | K8: 1500 | M8: =IF(N($J8)+N($K8)+N($L8)=0,"",N($J8)+N($K8)+N($L8)) -> 21500 | N8: 2W5zFJd6fzR | O8: https://ozon.onelink.me/SNMZ/ik1u4ho0 | R8: - | S8: https://vk.ru/clip-235277864_456239553?c=1 | T8: Да | U8: 148800 | V8: =IF(N($U8)=0,"",$M8/$U8) -> 0.14448925 | W8: 318 | X8: 201 | Y8: =IF(N($W8)=0,"",$M8/$W8) -> 67.610063 | Z8: 101 | AA8: 6 | AB8: 11800 | AD8: 6 | AE8: =AB8/AD8 -> 1966.6667 | AF8: =IF(OR(N($AD8)=0,$AE8=""),"",ROUND($AD8*$AE8,0)) -> 11800 | AG8: =IF(N($AD8)=0,"",ROUND($M8/$AD8,0)) -> 3583 | AH8: =IF(N($AA8)=0,"",ROUND($M8/$AA8,0)) -> 3583 | AI8: Aminotrigger-Fish
A9: https://max.ru/batya_ilin | B9: =IF($A9="","",IFERROR(HYPERLINK(VLOOKUP($A9,'Мои блогеры'!$A:$N,14,0),"🔗 открыть"),"")) -> 🔗 открыть | C9: =IFERROR(VLOOKUP($A9,'Мои блогеры'!$A:$N,5,0),"") -> 2600 | D9: =IFERROR(VLOOKUP($A9,'Мои блогеры'!$A:$N,2,0),"") -> MAX | E9: Ozon | F9: 22 | G9: v1 | H9: 46266 | I9: Вышло | J9: =IFERROR(VLOOKUP($A9,'Мои блогеры'!$A:$N,8,0),"") -> 0 | M9: 0 | N9: 2W5zFJkWcQ9 | O9: https://ozon.onelink.me/SNMZ/5enzywu9 | R9: - | S9: https://max.ru/batya_ilin/AaBdXlvIQR8 | T9: Да | U9: 1823 | V9: =IF(N($U9)=0,"",$M9/$U9) -> 0 | W9: 34 | X9: 34 | Y9: =IF(N($W9)=0,"",$M9/$W9) -> 0 | Z9: 8 | AA9: 2 | AB9: 3800 | AD9: 2 | AE9: =AB9/AD9 -> 1900 | AF9: =IF(OR(N($AD9)=0,$AE9=""),"",ROUND($AD9*$AE9,0)) -> 3800 | AG9: =IF(N($AD9)=0,"",ROUND($M9/$AD9,0)) -> 0 | AH9: =IF(N($AA9)=0,"",ROUND($M9/$AA9,0)) -> 0 | AI9: Aminotrigger-Fish
A10: https://vk.ru/fishinglifetv | B10: =IF($A10="","",IFERROR(HYPERLINK(VLOOKUP($A10,'Мои блогеры'!$A:$N,14,0),"🔗 открыть"),"")) -> 🔗 открыть | C10: =IFERROR(VLOOKUP($A10,'Мои блогеры'!$A:$N,5,0),"") -> 7800 | D10: =IFERROR(VLOOKUP($A10,'Мои блогеры'!$A:$N,2,0),"") -> VK | E10: Ozon | G10: t30 | H10: 46268 | I10: Вышло | J10: доп размещение | M10: 0 | O10: https://ozon.onelink.me/SNMZ/fmla4pxl | R10: - | S10: https://vk.ru/wall-226894765_699 | T10: Да | U10: 1002 | V10: =IF(N($U10)=0,"",$M10/$U10) -> 0 | W10: 51 | X10: - | Y10: =IF(N($W10)=0,"",$M10/$W10) -> 0 | Z10: 21 | AA10: 9 | AB10: =1900+13300+1900 -> 17100 | AD10: 9 | AE10: =AB10/AD10 -> 1900 | AF10: =IF(OR(N($AD10)=0,$AE10=""),"",ROUND($AD10*$AE10,0)) -> 17100 | AG10: =IF(N($AD10)=0,"",ROUND($M10/$AD10,0)) -> 0 | AH10: =IF(N($AA10)=0,"",ROUND($M10/$AA10,0)) -> 0 | AI10: Aminotrigger-Fish
A11: Итого: 1–7 сентябрь | I11: =COUNTIF(I7:I10,"Вышло")&" / "&COUNTA(A7:A10) -> 4 / 4 | J11: =SUM(J7:J10) -> 50000 | K11: =SUM(K7:K10) -> 3000 | L11: =SUM(L7:L10) -> 0 | M11: =SUM(M7:M10) -> 53000 | N11: =SUM(N7:N10) -> 0 | O11: =SUM(O7:O10) -> 0 | P11: =SUM(P7:P10) -> 0 | Q11: =SUM(Q7:Q10) -> 0 | ... U11: =SUM(U7:U10) -> 736725 | V11: =IF(N($U11)=0,"",$M11/$U11) -> 0.071940005 | W11: =SUM(W7:W10) -> 403 | X11: =SUM(X7:X10) -> 235 | Y11: =IF(N($W11)=0,"",$M11/$W11) -> 131.51365 | Z11: =SUM(Z7:Z10) -> 130 | AA11: =SUM(AA7:AA10) -> 19 | AB11: =SUM(AB7:AB10) -> 34860 | AC11: =SUM(AC7:AC10) -> 0 | AD11: =SUM(AD7:AD10) -> 19 | AE11: =SUM(AE7:AE10) -> 6846.6667 | AF11: =SUM(AF7:AF10) -> 34860 | AG11: =AF11/AD11 -> 1834.7368 | AH11: =IF(N($AA11)=0,"",ROUND($M11/$AA11,0)) -> 2789
A12: НЕДЕЛЯ —8–14 сентября
A13: ОРЗ ТВ - Охотники и Рыболовы ЗАПОЛЯРЬЯ | B13: =IF($A13="","",IFERROR(HYPERLINK(VLOOKUP($A13,'Мои блогеры'!$A:$N,14,0),"🔗 открыть"),"")) -> 🔗 открыть | C13: =IFERROR(VLOOKUP($A13,'Мои блогеры'!$A:$N,5,0),"") -> 171000 | D13: =IFERROR(VLOOKUP($A13,'Мои блогеры'!$A:$N,2,0),"") -> YouTube | E13: Ozon | F13: 10 | G13: своя подача общая | H13: 46273 | I13: Вышло | J13: =IFERROR(VLOOKUP($A13,'Мои блогеры'!$A:$N,8,0),"") -> 35000 | K13: 1000 | L13: 750 | M13: =IF(N($J13)+N($K13)+N($L13)=0,"",N($J13)+N($K13)+N($L13)) -> 36750 | O13: https://ozon.ru/product/aminotrigger-fish-aromatizator-dlya-rybalki-250-ml-5340361400?hs=1&utm_campaign=vendor_org_4202727_youohotnikinao&utm_content=video&utm_medium=blog&utm_source=youtube&utm_term=youohotnikinao | P13: https://aminotriggerfish.mobz.market/nsd | S13: https://www.youtube.com/watch?v=nSfzw0ZV1RM | T13: Нет | U13: 17000 | V13: =IF(N($U13)=0,"",$M13/$U13) -> 2.1617647 | W13: 27 | X13: 27 | Y13: =IF(N($W13)=0,"",$M13/$W13) -> 1361.1111 | Z13: 12 | AA13: 6 | AB13: 11400 | AD13: 6 | AE13: =AB13/AD13 -> 1900 | AF13: =IF(OR(N($AD13)=0,$AE13=""),"",ROUND($AD13*$AE13,0)) -> 11400 | AG13: =IF(N($AD13)=0,"",ROUND($M13/$AD13,0)) -> 6125 | AH13: =IF(N($AA13)=0,"",ROUND($M13/$AA13,0)) -> 6125 | AI13: Aminotrigger-Fish | AL13: полная интеграция дольше набирает охват
